<robot name = "robot">
    <link name="torso">
        <inertial>
            <origin xyz="0 0 1.25" rpy="0 0 0"/>
            <mass value="1" />
            <inertia ixx="100" ixy="0" ixz="0" iyy="100" iyz="0" izz="100" />
        </inertial>
        <visual>
            <origin xyz="0 0 1.25" rpy="0 0 0"/>
            <geometry>
                <box size="1 3 0.5" />
            </geometry>
            <material name="Cyan">
                <color rgba="0 1.0 1.0 1.0"/>
            </material>
        </visual>
        <collision>
            <origin xyz="0 0 1.25" rpy="0 0 0"/>
            <geometry>
                <box size="1 3 0.5" />
            </geometry>
        </collision>
    </link>
    <joint name="torso_rightleg" type="revolute">
       <parent link="torso"/>
       <child  link="rightleg"/>
       <origin rpy="0 0 0" xyz="0.5 0.5 1" />
     <axis xyz="0 1 0"/>
       <limit effort="0.0" lower="-3.14159" upper="3.14159" velocity="0.0"/>
    </joint>
    <link name="rightleg">
        <inertial>
            <origin xyz="0.5 0.25 0" rpy="0 0 0"/>
            <mass value="1" />
            <inertia ixx="100" ixy="0" ixz="0" iyy="100" iyz="0" izz="100" />
        </inertial>
        <visual>
            <origin xyz="0.5 0.25 0" rpy="0 0 0"/>
            <geometry>
                <box size="2 0.2 0.5" />
            </geometry>
            <material name="Cyan">
                <color rgba="0 1.0 1.0 1.0"/>
            </material>
        </visual>
        <collision>
            <origin xyz="0.5 0.25 0" rpy="0 0 0"/>
            <geometry>
                <box size="2 0.2 0.5" />
            </geometry>
        </collision>
    </link>
    <joint name="rightleg_rightleg2" type="revolute">
       <parent link="rightleg"/>
       <child  link="rightleg2"/>
       <origin rpy="0 0 0" xyz="1.5 0.25 0" />
     <axis xyz="0 1 0"/>
       <limit effort="0.0" lower="-3.14159" upper="3.14159" velocity="0.0"/>
    </joint>
    <link name="rightleg2">
        <inertial>
            <origin xyz="0 0 -0.5" rpy="0 0 0"/>
            <mass value="1" />
            <inertia ixx="100" ixy="0" ixz="0" iyy="100" iyz="0" izz="100" />
        </inertial>
        <visual>
            <origin xyz="0 0 -0.5" rpy="0 0 0"/>
            <geometry>
                <box size="0.2 0.2 1.5" />
            </geometry>
            <material name="Cyan">
                <color rgba="0 1.0 1.0 1.0"/>
            </material>
        </visual>
        <collision>
            <origin xyz="0 0 -0.5" rpy="0 0 0"/>
            <geometry>
                <box size="0.2 0.2 1.5" />
            </geometry>
        </collision>
    </link>
    <joint name="torso_frontleg" type="revolute">
       <parent link="torso"/>
       <child  link="frontleg"/>
       <origin rpy="0 0 0" xyz="0.5 -0.5 1" />
     <axis xyz="0 1 0"/>
       <limit effort="0.0" lower="-3.14159" upper="3.14159" velocity="0.0"/>
    </joint>
    <link name="frontleg">
        <inertial>
            <origin xyz="0.5 -0.25 0" rpy="0 0 0"/>
            <mass value="1" />
            <inertia ixx="100" ixy="0" ixz="0" iyy="100" iyz="0" izz="100" />
        </inertial>
        <visual>
            <origin xyz="0.5 -0.25 0" rpy="0 0 0"/>
            <geometry>
                <box size="2 0.2 0.5" />
            </geometry>
            <material name="Cyan">
                <color rgba="0 1.0 1.0 1.0"/>
            </material>
        </visual>
        <collision>
            <origin xyz="0.5 -0.25 0" rpy="0 0 0"/>
            <geometry>
                <box size="2 0.2 0.5" />
            </geometry>
        </collision>
    </link>
    <joint name="frontleg_frontleg2" type="revolute">
       <parent link="frontleg"/>
       <child  link="frontleg2"/>
       <origin rpy="0 0 0" xyz="1.5 -0.25 0" />
     <axis xyz="0 1 0"/>
       <limit effort="0.0" lower="-3.14159" upper="3.14159" velocity="0.0"/>
    </joint>
    <link name="frontleg2">
        <inertial>
            <origin xyz="0 0 -0.5" rpy="0 0 0"/>
            <mass value="1" />
            <inertia ixx="100" ixy="0" ixz="0" iyy="100" iyz="0" izz="100" />
        </inertial>
        <visual>
            <origin xyz="0 0 -0.5" rpy="0 0 0"/>
            <geometry>
                <box size="0.2 0.2 1.5" />
            </geometry>
            <material name="Cyan">
                <color rgba="0 1.0 1.0 1.0"/>
            </material>
        </visual>
        <collision>
            <origin xyz="0 0 -0.5" rpy="0 0 0"/>
            <geometry>
                <box size="0.2 0.2 1.5" />
            </geometry>
        </collision>
    </link>
    <joint name="torso_backleg" type="revolute">
       <parent link="torso"/>
       <child  link="backleg"/>
       <origin rpy="0 0 0" xyz="-0.5 -0.5 1" />
     <axis xyz="0 1 0"/>
       <limit effort="0.0" lower="-3.14159" upper="3.14159" velocity="0.0"/>
    </joint>
    <link name="backleg">
        <inertial>
            <origin xyz="-0.5 -0.25 0" rpy="0 0 0"/>
            <mass value="1" />
            <inertia ixx="100" ixy="0" ixz="0" iyy="100" iyz="0" izz="100" />
        </inertial>
        <visual>
            <origin xyz="-0.5 -0.25 0" rpy="0 0 0"/>
            <geometry>
                <box size="2 0.2 0.5" />
            </geometry>
            <material name="Cyan">
                <color rgba="0 1.0 1.0 1.0"/>
            </material>
        </visual>
        <collision>
            <origin xyz="-0.5 -0.25 0" rpy="0 0 0"/>
            <geometry>
                <box size="2 0.2 0.5" />
            </geometry>
        </collision>
    </link>
    <joint name="backleg_backleg2" type="revolute">
       <parent link="backleg"/>
       <child  link="backleg2"/>
       <origin rpy="0 0 0" xyz="-1.5 -0.25 0" />
     <axis xyz="0 1 0"/>
       <limit effort="0.0" lower="-3.14159" upper="3.14159" velocity="0.0"/>
    </joint>
    <link name="backleg2">
        <inertial>
            <origin xyz="0 0 -0.5" rpy="0 0 0"/>
            <mass value="1" />
            <inertia ixx="100" ixy="0" ixz="0" iyy="100" iyz="0" izz="100" />
        </inertial>
        <visual>
            <origin xyz="0 0 -0.5" rpy="0 0 0"/>
            <geometry>
                <box size="0.2 0.2 1.5" />
            </geometry>
            <material name="Cyan">
                <color rgba="0 1.0 1.0 1.0"/>
            </material>
        </visual>
        <collision>
            <origin xyz="0 0 -0.5" rpy="0 0 0"/>
            <geometry>
                <box size="0.2 0.2 1.5" />
            </geometry>
        </collision>
    </link>
    <joint name="torso_leftleg" type="revolute">
       <parent link="torso"/>
       <child  link="leftleg"/>
       <origin rpy="0 0 0" xyz="-0.5 0.5 1" />
     <axis xyz="0 1 0"/>
       <limit effort="0.0" lower="-3.14159" upper="3.14159" velocity="0.0"/>
    </joint>
    <link name="leftleg">
        <inertial>
            <origin xyz="-0.5 0.25 0" rpy="0 0 0"/>
            <mass value="1" />
            <inertia ixx="100" ixy="0" ixz="0" iyy="100" iyz="0" izz="100" />
        </inertial>
        <visual>
            <origin xyz="-0.5 0.25 0" rpy="0 0 0"/>
            <geometry>
                <box size="2 0.2 0.5" />
            </geometry>
            <material name="Cyan">
                <color rgba="0 1.0 1.0 1.0"/>
            </material>
        </visual>
        <collision>
            <origin xyz="-0.5 0.25 0" rpy="0 0 0"/>
            <geometry>
                <box size="2 0.2 0.5" />
            </geometry>
        </collision>
    </link>
    <joint name="leftleg_leftleg2" type="revolute">
       <parent link="leftleg"/>
       <child  link="leftleg2"/>
       <origin rpy="0 0 0" xyz="-1.5 0.25 0" />
     <axis xyz="0 1 0"/>
       <limit effort="0.0" lower="-3.14159" upper="3.14159" velocity="0.0"/>
    </joint>
    <link name="leftleg2">
        <inertial>
            <origin xyz="0 0 -0.5" rpy="0 0 0"/>
            <mass value="1" />
            <inertia ixx="100" ixy="0" ixz="0" iyy="100" iyz="0" izz="100" />
        </inertial>
        <visual>
            <origin xyz="0 0 -0.5" rpy="0 0 0"/>
            <geometry>
                <box size="0.2 0.2 1.5" />
            </geometry>
            <material name="Cyan">
                <color rgba="0 1.0 1.0 1.0"/>
            </material>
        </visual>
        <collision>
            <origin xyz="0 0 -0.5" rpy="0 0 0"/>
            <geometry>
                <box size="0.2 0.2 1.5" />
            </geometry>
        </collision>
    </link>
</robot>