<robot name = "robot">
    <link name="body0">
        <inertial>
            <origin xyz="0.14348779535100614 0 0.9396569410464768" rpy="0 0 0"/>
            <mass value="1" />
            <inertia ixx="100" ixy="0" ixz="0" iyy="100" iyz="0" izz="100" />
        </inertial>
        <visual>
            <origin xyz="0.14348779535100614 0 0.9396569410464768" rpy="0 0 0"/>
            <geometry>
                <box size="0.2869755907020123 0.4673290201974972 0.5839520405944711" />
            </geometry>
            <material name="red">
                <color rgba="0 0 1.0 1.0"/>
            </material>
        </visual>
        <collision>
            <origin xyz="0.14348779535100614 0 0.9396569410464768" rpy="0 0 0"/>
            <geometry>
                <box size="0.2869755907020123 0.4673290201974972 0.5839520405944711" />
            </geometry>
        </collision>
    </link>
    <link name="RightUpperLeg0">
        <inertial>
            <origin xyz="0 -0.07031377244518003 -0.13400174466315465" rpy="0 0 0"/>
            <mass value="1" />
            <inertia ixx="100" ixy="0" ixz="0" iyy="100" iyz="0" izz="100" />
        </inertial>
        <visual>
            <origin xyz="0 -0.07031377244518003 -0.13400174466315465" rpy="0 0 0"/>
            <geometry>
                <box size="0.31046453395357687 0.14062754489036006 0.2680034893263093" />
            </geometry>
            <material name="red">
                <color rgba="0 0 1.0 1.0"/>
            </material>
        </visual>
        <collision>
            <origin xyz="0 -0.07031377244518003 -0.13400174466315465" rpy="0 0 0"/>
            <geometry>
                <box size="0.31046453395357687 0.14062754489036006 0.2680034893263093" />
            </geometry>
        </collision>
    </link>
    <link name="LeftUpperLeg0">
        <inertial>
            <origin xyz="0 0.07031377244518003 -0.13400174466315465" rpy="0 0 0"/>
            <mass value="1" />
            <inertia ixx="100" ixy="0" ixz="0" iyy="100" iyz="0" izz="100" />
        </inertial>
        <visual>
            <origin xyz="0 0.07031377244518003 -0.13400174466315465" rpy="0 0 0"/>
            <geometry>
                <box size="0.31046453395357687 0.14062754489036006 0.2680034893263093" />
            </geometry>
            <material name="red">
                <color rgba="0 0 1.0 1.0"/>
            </material>
        </visual>
        <collision>
            <origin xyz="0 0.07031377244518003 -0.13400174466315465" rpy="0 0 0"/>
            <geometry>
                <box size="0.31046453395357687 0.14062754489036006 0.2680034893263093" />
            </geometry>
        </collision>
    </link>
    <link name="RightLowerLeg0">
        <inertial>
            <origin xyz="0 0 -0.3358267258600838" rpy="0 0 0"/>
            <mass value="1" />
            <inertia ixx="100" ixy="0" ixz="0" iyy="100" iyz="0" izz="100" />
        </inertial>
        <visual>
            <origin xyz="0 0 -0.3358267258600838" rpy="0 0 0"/>
            <geometry>
                <box size="0.3852421474780987 0.2659167059565204 0.6716534517201675" />
            </geometry>
            <material name="green">
                <color rgba="0 1.0 0 1.0"/>
            </material>
        </visual>
        <collision>
            <origin xyz="0 0 -0.3358267258600838" rpy="0 0 0"/>
            <geometry>
                <box size="0.3852421474780987 0.2659167059565204 0.6716534517201675" />
            </geometry>
        </collision>
    </link>
    <link name="LeftLowerLeg0">
        <inertial>
            <origin xyz="0 0 -0.3358267258600838" rpy="0 0 0"/>
            <mass value="1" />
            <inertia ixx="100" ixy="0" ixz="0" iyy="100" iyz="0" izz="100" />
        </inertial>
        <visual>
            <origin xyz="0 0 -0.3358267258600838" rpy="0 0 0"/>
            <geometry>
                <box size="0.3852421474780987 0.2659167059565204 0.6716534517201675" />
            </geometry>
            <material name="red">
                <color rgba="0 0 1.0 1.0"/>
            </material>
        </visual>
        <collision>
            <origin xyz="0 0 -0.3358267258600838" rpy="0 0 0"/>
            <geometry>
                <box size="0.3852421474780987 0.2659167059565204 0.6716534517201675" />
            </geometry>
        </collision>
    </link>
    <link name="body1">
        <inertial>
            <origin xyz="0.14348779535100614 0 0" rpy="0 0 0"/>
            <mass value="1" />
            <inertia ixx="100" ixy="0" ixz="0" iyy="100" iyz="0" izz="100" />
        </inertial>
        <visual>
            <origin xyz="0.14348779535100614 0 0" rpy="0 0 0"/>
            <geometry>
                <box size="0.2869755907020123 0.4673290201974972 0.5839520405944711" />
            </geometry>
            <material name="red">
                <color rgba="0 0 1.0 1.0"/>
            </material>
        </visual>
        <collision>
            <origin xyz="0.14348779535100614 0 0" rpy="0 0 0"/>
            <geometry>
                <box size="0.2869755907020123 0.4673290201974972 0.5839520405944711" />
            </geometry>
        </collision>
    </link>
    <link name="RightUpperLeg1">
        <inertial>
            <origin xyz="0 -0.07031377244518003 -0.13400174466315465" rpy="0 0 0"/>
            <mass value="1" />
            <inertia ixx="100" ixy="0" ixz="0" iyy="100" iyz="0" izz="100" />
        </inertial>
        <visual>
            <origin xyz="0 -0.07031377244518003 -0.13400174466315465" rpy="0 0 0"/>
            <geometry>
                <box size="0.31046453395357687 0.14062754489036006 0.2680034893263093" />
            </geometry>
            <material name="green">
                <color rgba="0 1.0 0 1.0"/>
            </material>
        </visual>
        <collision>
            <origin xyz="0 -0.07031377244518003 -0.13400174466315465" rpy="0 0 0"/>
            <geometry>
                <box size="0.31046453395357687 0.14062754489036006 0.2680034893263093" />
            </geometry>
        </collision>
    </link>
    <link name="LeftUpperLeg1">
        <inertial>
            <origin xyz="0 0.07031377244518003 -0.13400174466315465" rpy="0 0 0"/>
            <mass value="1" />
            <inertia ixx="100" ixy="0" ixz="0" iyy="100" iyz="0" izz="100" />
        </inertial>
        <visual>
            <origin xyz="0 0.07031377244518003 -0.13400174466315465" rpy="0 0 0"/>
            <geometry>
                <box size="0.31046453395357687 0.14062754489036006 0.2680034893263093" />
            </geometry>
            <material name="green">
                <color rgba="0 1.0 0 1.0"/>
            </material>
        </visual>
        <collision>
            <origin xyz="0 0.07031377244518003 -0.13400174466315465" rpy="0 0 0"/>
            <geometry>
                <box size="0.31046453395357687 0.14062754489036006 0.2680034893263093" />
            </geometry>
        </collision>
    </link>
    <link name="RightLowerLeg1">
        <inertial>
            <origin xyz="0 0 -0.3358267258600838" rpy="0 0 0"/>
            <mass value="1" />
            <inertia ixx="100" ixy="0" ixz="0" iyy="100" iyz="0" izz="100" />
        </inertial>
        <visual>
            <origin xyz="0 0 -0.3358267258600838" rpy="0 0 0"/>
            <geometry>
                <box size="0.3852421474780987 0.2659167059565204 0.6716534517201675" />
            </geometry>
            <material name="red">
                <color rgba="0 0 1.0 1.0"/>
            </material>
        </visual>
        <collision>
            <origin xyz="0 0 -0.3358267258600838" rpy="0 0 0"/>
            <geometry>
                <box size="0.3852421474780987 0.2659167059565204 0.6716534517201675" />
            </geometry>
        </collision>
    </link>
    <link name="LeftLowerLeg1">
        <inertial>
            <origin xyz="0 0 -0.3358267258600838" rpy="0 0 0"/>
            <mass value="1" />
            <inertia ixx="100" ixy="0" ixz="0" iyy="100" iyz="0" izz="100" />
        </inertial>
        <visual>
            <origin xyz="0 0 -0.3358267258600838" rpy="0 0 0"/>
            <geometry>
                <box size="0.3852421474780987 0.2659167059565204 0.6716534517201675" />
            </geometry>
            <material name="red">
                <color rgba="0 0 1.0 1.0"/>
            </material>
        </visual>
        <collision>
            <origin xyz="0 0 -0.3358267258600838" rpy="0 0 0"/>
            <geometry>
                <box size="0.3852421474780987 0.2659167059565204 0.6716534517201675" />
            </geometry>
        </collision>
    </link>
    <link name="body2">
        <inertial>
            <origin xyz="0.14348779535100614 0 0" rpy="0 0 0"/>
            <mass value="1" />
            <inertia ixx="100" ixy="0" ixz="0" iyy="100" iyz="0" izz="100" />
        </inertial>
        <visual>
            <origin xyz="0.14348779535100614 0 0" rpy="0 0 0"/>
            <geometry>
                <box size="0.2869755907020123 0.4673290201974972 0.5839520405944711" />
            </geometry>
            <material name="green">
                <color rgba="0 1.0 0 1.0"/>
            </material>
        </visual>
        <collision>
            <origin xyz="0.14348779535100614 0 0" rpy="0 0 0"/>
            <geometry>
                <box size="0.2869755907020123 0.4673290201974972 0.5839520405944711" />
            </geometry>
        </collision>
    </link>
    <link name="RightUpperLeg2">
        <inertial>
            <origin xyz="0 -0.07031377244518003 -0.13400174466315465" rpy="0 0 0"/>
            <mass value="1" />
            <inertia ixx="100" ixy="0" ixz="0" iyy="100" iyz="0" izz="100" />
        </inertial>
        <visual>
            <origin xyz="0 -0.07031377244518003 -0.13400174466315465" rpy="0 0 0"/>
            <geometry>
                <box size="0.31046453395357687 0.14062754489036006 0.2680034893263093" />
            </geometry>
            <material name="red">
                <color rgba="0 0 1.0 1.0"/>
            </material>
        </visual>
        <collision>
            <origin xyz="0 -0.07031377244518003 -0.13400174466315465" rpy="0 0 0"/>
            <geometry>
                <box size="0.31046453395357687 0.14062754489036006 0.2680034893263093" />
            </geometry>
        </collision>
    </link>
    <link name="LeftUpperLeg2">
        <inertial>
            <origin xyz="0 0.07031377244518003 -0.13400174466315465" rpy="0 0 0"/>
            <mass value="1" />
            <inertia ixx="100" ixy="0" ixz="0" iyy="100" iyz="0" izz="100" />
        </inertial>
        <visual>
            <origin xyz="0 0.07031377244518003 -0.13400174466315465" rpy="0 0 0"/>
            <geometry>
                <box size="0.31046453395357687 0.14062754489036006 0.2680034893263093" />
            </geometry>
            <material name="red">
                <color rgba="0 0 1.0 1.0"/>
            </material>
        </visual>
        <collision>
            <origin xyz="0 0.07031377244518003 -0.13400174466315465" rpy="0 0 0"/>
            <geometry>
                <box size="0.31046453395357687 0.14062754489036006 0.2680034893263093" />
            </geometry>
        </collision>
    </link>
    <link name="RightLowerLeg2">
        <inertial>
            <origin xyz="0 0 -0.3358267258600838" rpy="0 0 0"/>
            <mass value="1" />
            <inertia ixx="100" ixy="0" ixz="0" iyy="100" iyz="0" izz="100" />
        </inertial>
        <visual>
            <origin xyz="0 0 -0.3358267258600838" rpy="0 0 0"/>
            <geometry>
                <box size="0.3852421474780987 0.2659167059565204 0.6716534517201675" />
            </geometry>
            <material name="green">
                <color rgba="0 1.0 0 1.0"/>
            </material>
        </visual>
        <collision>
            <origin xyz="0 0 -0.3358267258600838" rpy="0 0 0"/>
            <geometry>
                <box size="0.3852421474780987 0.2659167059565204 0.6716534517201675" />
            </geometry>
        </collision>
    </link>
    <link name="LeftLowerLeg2">
        <inertial>
            <origin xyz="0 0 -0.3358267258600838" rpy="0 0 0"/>
            <mass value="1" />
            <inertia ixx="100" ixy="0" ixz="0" iyy="100" iyz="0" izz="100" />
        </inertial>
        <visual>
            <origin xyz="0 0 -0.3358267258600838" rpy="0 0 0"/>
            <geometry>
                <box size="0.3852421474780987 0.2659167059565204 0.6716534517201675" />
            </geometry>
            <material name="red">
                <color rgba="0 0 1.0 1.0"/>
            </material>
        </visual>
        <collision>
            <origin xyz="0 0 -0.3358267258600838" rpy="0 0 0"/>
            <geometry>
                <box size="0.3852421474780987 0.2659167059565204 0.6716534517201675" />
            </geometry>
        </collision>
    </link>
    <link name="body3">
        <inertial>
            <origin xyz="0.14348779535100614 0 0" rpy="0 0 0"/>
            <mass value="1" />
            <inertia ixx="100" ixy="0" ixz="0" iyy="100" iyz="0" izz="100" />
        </inertial>
        <visual>
            <origin xyz="0.14348779535100614 0 0" rpy="0 0 0"/>
            <geometry>
                <box size="0.2869755907020123 0.4673290201974972 0.5839520405944711" />
            </geometry>
            <material name="red">
                <color rgba="0 0 1.0 1.0"/>
            </material>
        </visual>
        <collision>
            <origin xyz="0.14348779535100614 0 0" rpy="0 0 0"/>
            <geometry>
                <box size="0.2869755907020123 0.4673290201974972 0.5839520405944711" />
            </geometry>
        </collision>
    </link>
    <link name="RightUpperLeg3">
        <inertial>
            <origin xyz="0 -0.07031377244518003 -0.13400174466315465" rpy="0 0 0"/>
            <mass value="1" />
            <inertia ixx="100" ixy="0" ixz="0" iyy="100" iyz="0" izz="100" />
        </inertial>
        <visual>
            <origin xyz="0 -0.07031377244518003 -0.13400174466315465" rpy="0 0 0"/>
            <geometry>
                <box size="0.31046453395357687 0.14062754489036006 0.2680034893263093" />
            </geometry>
            <material name="red">
                <color rgba="0 0 1.0 1.0"/>
            </material>
        </visual>
        <collision>
            <origin xyz="0 -0.07031377244518003 -0.13400174466315465" rpy="0 0 0"/>
            <geometry>
                <box size="0.31046453395357687 0.14062754489036006 0.2680034893263093" />
            </geometry>
        </collision>
    </link>
    <link name="LeftUpperLeg3">
        <inertial>
            <origin xyz="0 0.07031377244518003 -0.13400174466315465" rpy="0 0 0"/>
            <mass value="1" />
            <inertia ixx="100" ixy="0" ixz="0" iyy="100" iyz="0" izz="100" />
        </inertial>
        <visual>
            <origin xyz="0 0.07031377244518003 -0.13400174466315465" rpy="0 0 0"/>
            <geometry>
                <box size="0.31046453395357687 0.14062754489036006 0.2680034893263093" />
            </geometry>
            <material name="green">
                <color rgba="0 1.0 0 1.0"/>
            </material>
        </visual>
        <collision>
            <origin xyz="0 0.07031377244518003 -0.13400174466315465" rpy="0 0 0"/>
            <geometry>
                <box size="0.31046453395357687 0.14062754489036006 0.2680034893263093" />
            </geometry>
        </collision>
    </link>
    <link name="RightLowerLeg3">
        <inertial>
            <origin xyz="0 0 -0.3358267258600838" rpy="0 0 0"/>
            <mass value="1" />
            <inertia ixx="100" ixy="0" ixz="0" iyy="100" iyz="0" izz="100" />
        </inertial>
        <visual>
            <origin xyz="0 0 -0.3358267258600838" rpy="0 0 0"/>
            <geometry>
                <box size="0.3852421474780987 0.2659167059565204 0.6716534517201675" />
            </geometry>
            <material name="green">
                <color rgba="0 1.0 0 1.0"/>
            </material>
        </visual>
        <collision>
            <origin xyz="0 0 -0.3358267258600838" rpy="0 0 0"/>
            <geometry>
                <box size="0.3852421474780987 0.2659167059565204 0.6716534517201675" />
            </geometry>
        </collision>
    </link>
    <link name="LeftLowerLeg3">
        <inertial>
            <origin xyz="0 0 -0.3358267258600838" rpy="0 0 0"/>
            <mass value="1" />
            <inertia ixx="100" ixy="0" ixz="0" iyy="100" iyz="0" izz="100" />
        </inertial>
        <visual>
            <origin xyz="0 0 -0.3358267258600838" rpy="0 0 0"/>
            <geometry>
                <box size="0.3852421474780987 0.2659167059565204 0.6716534517201675" />
            </geometry>
            <material name="green">
                <color rgba="0 1.0 0 1.0"/>
            </material>
        </visual>
        <collision>
            <origin xyz="0 0 -0.3358267258600838" rpy="0 0 0"/>
            <geometry>
                <box size="0.3852421474780987 0.2659167059565204 0.6716534517201675" />
            </geometry>
        </collision>
    </link>
    <joint name="body0_body1" type="revolute">
       <parent link="body0"/>
       <child  link="body1"/>
       <origin rpy="0 0 0" xyz="0.2869755907020123 0 0.9396569410464768" />
     <axis xyz="0 1 0"/>
       <limit effort="0.0" lower="-3.14159" upper="3.14159" velocity="0.0"/>
    </joint>
    <joint name="body0_RightUpperLeg0" type="revolute">
       <parent link="body0"/>
       <child  link="RightUpperLeg0"/>
       <origin rpy="0 0 0" xyz="0.14348779535100614 -0.2336645100987486 0.9396569410464768" />
     <axis xyz="0 1 0"/>
       <limit effort="0.0" lower="-3.14159" upper="3.14159" velocity="0.0"/>
    </joint>
    <joint name="body0_LeftUpperLeg0" type="revolute">
       <parent link="body0"/>
       <child  link="LeftUpperLeg0"/>
       <origin rpy="0 0 0" xyz="0.14348779535100614 0.2336645100987486 0.9396569410464768" />
     <axis xyz="0 1 0"/>
       <limit effort="0.0" lower="-3.14159" upper="3.14159" velocity="0.0"/>
    </joint>
    <joint name="RightUpperLeg0_RightLowerLeg0" type="revolute">
       <parent link="RightUpperLeg0"/>
       <child  link="RightLowerLeg0"/>
       <origin rpy="0 0 0" xyz="0 -0.07031377244518003 -0.2680034893263093" />
     <axis xyz="0 1 0"/>
       <limit effort="0.0" lower="-3.14159" upper="3.14159" velocity="0.0"/>
    </joint>
    <joint name="LeftUpperLeg0_LeftLowerLeg0" type="revolute">
       <parent link="LeftUpperLeg0"/>
       <child  link="LeftLowerLeg0"/>
       <origin rpy="0 0 0" xyz="0 0.07031377244518003 -0.2680034893263093" />
     <axis xyz="0 1 0"/>
       <limit effort="0.0" lower="-3.14159" upper="3.14159" velocity="0.0"/>
    </joint>
    <joint name="body1_body2" type="revolute">
       <parent link="body1"/>
       <child  link="body2"/>
       <origin rpy="0 0 0" xyz="0.2869755907020123 0 0" />
     <axis xyz="0 1 0"/>
       <limit effort="0.0" lower="-3.14159" upper="3.14159" velocity="0.0"/>
    </joint>
    <joint name="body1_RightUpperLeg1" type="revolute">
       <parent link="body1"/>
       <child  link="RightUpperLeg1"/>
       <origin rpy="0 0 0" xyz="0.14348779535100614 -0.2336645100987486 0" />
     <axis xyz="0 1 0"/>
       <limit effort="0.0" lower="-3.14159" upper="3.14159" velocity="0.0"/>
    </joint>
    <joint name="body1_LeftUpperLeg1" type="revolute">
       <parent link="body1"/>
       <child  link="LeftUpperLeg1"/>
       <origin rpy="0 0 0" xyz="0.14348779535100614 0.2336645100987486 0" />
     <axis xyz="0 1 0"/>
       <limit effort="0.0" lower="-3.14159" upper="3.14159" velocity="0.0"/>
    </joint>
    <joint name="RightUpperLeg1_RightLowerLeg1" type="revolute">
       <parent link="RightUpperLeg1"/>
       <child  link="RightLowerLeg1"/>
       <origin rpy="0 0 0" xyz="0 -0.07031377244518003 -0.2680034893263093" />
     <axis xyz="0 1 0"/>
       <limit effort="0.0" lower="-3.14159" upper="3.14159" velocity="0.0"/>
    </joint>
    <joint name="LeftUpperLeg1_LeftLowerLeg1" type="revolute">
       <parent link="LeftUpperLeg1"/>
       <child  link="LeftLowerLeg1"/>
       <origin rpy="0 0 0" xyz="0 0.07031377244518003 -0.2680034893263093" />
     <axis xyz="0 1 0"/>
       <limit effort="0.0" lower="-3.14159" upper="3.14159" velocity="0.0"/>
    </joint>
    <joint name="body2_body3" type="revolute">
       <parent link="body2"/>
       <child  link="body3"/>
       <origin rpy="0 0 0" xyz="0.2869755907020123 0 0" />
     <axis xyz="0 1 0"/>
       <limit effort="0.0" lower="-3.14159" upper="3.14159" velocity="0.0"/>
    </joint>
    <joint name="body2_RightUpperLeg2" type="revolute">
       <parent link="body2"/>
       <child  link="RightUpperLeg2"/>
       <origin rpy="0 0 0" xyz="0.14348779535100614 -0.2336645100987486 0" />
     <axis xyz="0 1 0"/>
       <limit effort="0.0" lower="-3.14159" upper="3.14159" velocity="0.0"/>
    </joint>
    <joint name="body2_LeftUpperLeg2" type="revolute">
       <parent link="body2"/>
       <child  link="LeftUpperLeg2"/>
       <origin rpy="0 0 0" xyz="0.14348779535100614 0.2336645100987486 0" />
     <axis xyz="0 1 0"/>
       <limit effort="0.0" lower="-3.14159" upper="3.14159" velocity="0.0"/>
    </joint>
    <joint name="RightUpperLeg2_RightLowerLeg2" type="revolute">
       <parent link="RightUpperLeg2"/>
       <child  link="RightLowerLeg2"/>
       <origin rpy="0 0 0" xyz="0 -0.07031377244518003 -0.2680034893263093" />
     <axis xyz="0 1 0"/>
       <limit effort="0.0" lower="-3.14159" upper="3.14159" velocity="0.0"/>
    </joint>
    <joint name="LeftUpperLeg2_LeftLowerLeg2" type="revolute">
       <parent link="LeftUpperLeg2"/>
       <child  link="LeftLowerLeg2"/>
       <origin rpy="0 0 0" xyz="0.31046453395357687 0 0" />
     <axis xyz="0 1 0"/>
       <limit effort="0.0" lower="-3.14159" upper="3.14159" velocity="0.0"/>
    </joint>
    <joint name="body3_RightUpperLeg3" type="revolute">
       <parent link="body3"/>
       <child  link="RightUpperLeg3"/>
       <origin rpy="0 0 0" xyz="0.14348779535100614 -0.2336645100987486 0" />
     <axis xyz="0 1 0"/>
       <limit effort="0.0" lower="-3.14159" upper="3.14159" velocity="0.0"/>
    </joint>
    <joint name="body3_LeftUpperLeg3" type="revolute">
       <parent link="body3"/>
       <child  link="LeftUpperLeg3"/>
       <origin rpy="0 0 0" xyz="0.14348779535100614 0.2336645100987486 0" />
     <axis xyz="0 1 0"/>
       <limit effort="0.0" lower="-3.14159" upper="3.14159" velocity="0.0"/>
    </joint>
    <joint name="RightUpperLeg3_RightLowerLeg3" type="revolute">
       <parent link="RightUpperLeg3"/>
       <child  link="RightLowerLeg3"/>
       <origin rpy="0 0 0" xyz="0 -0.07031377244518003 -0.2680034893263093" />
     <axis xyz="0 1 0"/>
       <limit effort="0.0" lower="-3.14159" upper="3.14159" velocity="0.0"/>
    </joint>
    <joint name="LeftUpperLeg3_LeftLowerLeg3" type="revolute">
       <parent link="LeftUpperLeg3"/>
       <child  link="LeftLowerLeg3"/>
       <origin rpy="0 0 0" xyz="0 0.07031377244518003 -0.2680034893263093" />
     <axis xyz="0 1 0"/>
       <limit effort="0.0" lower="-3.14159" upper="3.14159" velocity="0.0"/>
    </joint>
</robot>