<robot name = "robot">
    <link name="body0">
        <inertial>
            <origin xyz="0.2869326528819695 0 0.8690886319756386" rpy="0 0 0"/>
            <mass value="1" />
            <inertia ixx="100" ixy="0" ixz="0" iyy="100" iyz="0" izz="100" />
        </inertial>
        <visual>
            <origin xyz="0.2869326528819695 0 0.8690886319756386" rpy="0 0 0"/>
            <geometry>
                <box size="0.573865305763939 0.34237454839187786 0.2602682185558036" />
            </geometry>
            <material name="red">
                <color rgba="0 0 1.0 1.0"/>
            </material>
        </visual>
        <collision>
            <origin xyz="0.2869326528819695 0 0.8690886319756386" rpy="0 0 0"/>
            <geometry>
                <box size="0.573865305763939 0.34237454839187786 0.2602682185558036" />
            </geometry>
        </collision>
    </link>
    <link name="RightUpperLeg0">
        <inertial>
            <origin xyz="0 -0.1548294037050802 -0.12998763564909746" rpy="0 0 0"/>
            <mass value="1" />
            <inertia ixx="100" ixy="0" ixz="0" iyy="100" iyz="0" izz="100" />
        </inertial>
        <visual>
            <origin xyz="0 -0.1548294037050802 -0.12998763564909746" rpy="0 0 0"/>
            <geometry>
                <box size="0.14632800192679904 0.3096588074101604 0.2599752712981949" />
            </geometry>
            <material name="red">
                <color rgba="0 0 1.0 1.0"/>
            </material>
        </visual>
        <collision>
            <origin xyz="0 -0.1548294037050802 -0.12998763564909746" rpy="0 0 0"/>
            <geometry>
                <box size="0.14632800192679904 0.3096588074101604 0.2599752712981949" />
            </geometry>
        </collision>
    </link>
    <link name="LeftUpperLeg0">
        <inertial>
            <origin xyz="0 0.1548294037050802 -0.12998763564909746" rpy="0 0 0"/>
            <mass value="1" />
            <inertia ixx="100" ixy="0" ixz="0" iyy="100" iyz="0" izz="100" />
        </inertial>
        <visual>
            <origin xyz="0 0.1548294037050802 -0.12998763564909746" rpy="0 0 0"/>
            <geometry>
                <box size="0.14632800192679904 0.3096588074101604 0.2599752712981949" />
            </geometry>
            <material name="green">
                <color rgba="0 1.0 0 1.0"/>
            </material>
        </visual>
        <collision>
            <origin xyz="0 0.1548294037050802 -0.12998763564909746" rpy="0 0 0"/>
            <geometry>
                <box size="0.14632800192679904 0.3096588074101604 0.2599752712981949" />
            </geometry>
        </collision>
    </link>
    <link name="RightLowerLeg0">
        <inertial>
            <origin xyz="0 0 -0.30455668033872185" rpy="0 0 0"/>
            <mass value="1" />
            <inertia ixx="100" ixy="0" ixz="0" iyy="100" iyz="0" izz="100" />
        </inertial>
        <visual>
            <origin xyz="0 0 -0.30455668033872185" rpy="0 0 0"/>
            <geometry>
                <box size="0.24555277287995952 0.2898213191802811 0.6091133606774437" />
            </geometry>
            <material name="green">
                <color rgba="0 1.0 0 1.0"/>
            </material>
        </visual>
        <collision>
            <origin xyz="0 0 -0.30455668033872185" rpy="0 0 0"/>
            <geometry>
                <box size="0.24555277287995952 0.2898213191802811 0.6091133606774437" />
            </geometry>
        </collision>
    </link>
    <link name="LeftLowerLeg0">
        <inertial>
            <origin xyz="0 0 -0.30455668033872185" rpy="0 0 0"/>
            <mass value="1" />
            <inertia ixx="100" ixy="0" ixz="0" iyy="100" iyz="0" izz="100" />
        </inertial>
        <visual>
            <origin xyz="0 0 -0.30455668033872185" rpy="0 0 0"/>
            <geometry>
                <box size="0.24555277287995952 0.2898213191802811 0.6091133606774437" />
            </geometry>
            <material name="green">
                <color rgba="0 1.0 0 1.0"/>
            </material>
        </visual>
        <collision>
            <origin xyz="0 0 -0.30455668033872185" rpy="0 0 0"/>
            <geometry>
                <box size="0.24555277287995952 0.2898213191802811 0.6091133606774437" />
            </geometry>
        </collision>
    </link>
    <link name="body1">
        <inertial>
            <origin xyz="0.2869326528819695 0 0" rpy="0 0 0"/>
            <mass value="1" />
            <inertia ixx="100" ixy="0" ixz="0" iyy="100" iyz="0" izz="100" />
        </inertial>
        <visual>
            <origin xyz="0.2869326528819695 0 0" rpy="0 0 0"/>
            <geometry>
                <box size="0.573865305763939 0.34237454839187786 0.2602682185558036" />
            </geometry>
            <material name="red">
                <color rgba="0 0 1.0 1.0"/>
            </material>
        </visual>
        <collision>
            <origin xyz="0.2869326528819695 0 0" rpy="0 0 0"/>
            <geometry>
                <box size="0.573865305763939 0.34237454839187786 0.2602682185558036" />
            </geometry>
        </collision>
    </link>
    <link name="RightUpperLeg1">
        <inertial>
            <origin xyz="0 -0.1548294037050802 -0.12998763564909746" rpy="0 0 0"/>
            <mass value="1" />
            <inertia ixx="100" ixy="0" ixz="0" iyy="100" iyz="0" izz="100" />
        </inertial>
        <visual>
            <origin xyz="0 -0.1548294037050802 -0.12998763564909746" rpy="0 0 0"/>
            <geometry>
                <box size="0.14632800192679904 0.3096588074101604 0.2599752712981949" />
            </geometry>
            <material name="red">
                <color rgba="0 0 1.0 1.0"/>
            </material>
        </visual>
        <collision>
            <origin xyz="0 -0.1548294037050802 -0.12998763564909746" rpy="0 0 0"/>
            <geometry>
                <box size="0.14632800192679904 0.3096588074101604 0.2599752712981949" />
            </geometry>
        </collision>
    </link>
    <link name="LeftUpperLeg1">
        <inertial>
            <origin xyz="0 0.1548294037050802 -0.12998763564909746" rpy="0 0 0"/>
            <mass value="1" />
            <inertia ixx="100" ixy="0" ixz="0" iyy="100" iyz="0" izz="100" />
        </inertial>
        <visual>
            <origin xyz="0 0.1548294037050802 -0.12998763564909746" rpy="0 0 0"/>
            <geometry>
                <box size="0.14632800192679904 0.3096588074101604 0.2599752712981949" />
            </geometry>
            <material name="red">
                <color rgba="0 0 1.0 1.0"/>
            </material>
        </visual>
        <collision>
            <origin xyz="0 0.1548294037050802 -0.12998763564909746" rpy="0 0 0"/>
            <geometry>
                <box size="0.14632800192679904 0.3096588074101604 0.2599752712981949" />
            </geometry>
        </collision>
    </link>
    <link name="RightLowerLeg1">
        <inertial>
            <origin xyz="0 0 -0.30455668033872185" rpy="0 0 0"/>
            <mass value="1" />
            <inertia ixx="100" ixy="0" ixz="0" iyy="100" iyz="0" izz="100" />
        </inertial>
        <visual>
            <origin xyz="0 0 -0.30455668033872185" rpy="0 0 0"/>
            <geometry>
                <box size="0.24555277287995952 0.2898213191802811 0.6091133606774437" />
            </geometry>
            <material name="green">
                <color rgba="0 1.0 0 1.0"/>
            </material>
        </visual>
        <collision>
            <origin xyz="0 0 -0.30455668033872185" rpy="0 0 0"/>
            <geometry>
                <box size="0.24555277287995952 0.2898213191802811 0.6091133606774437" />
            </geometry>
        </collision>
    </link>
    <link name="LeftLowerLeg1">
        <inertial>
            <origin xyz="0 0 -0.30455668033872185" rpy="0 0 0"/>
            <mass value="1" />
            <inertia ixx="100" ixy="0" ixz="0" iyy="100" iyz="0" izz="100" />
        </inertial>
        <visual>
            <origin xyz="0 0 -0.30455668033872185" rpy="0 0 0"/>
            <geometry>
                <box size="0.24555277287995952 0.2898213191802811 0.6091133606774437" />
            </geometry>
            <material name="green">
                <color rgba="0 1.0 0 1.0"/>
            </material>
        </visual>
        <collision>
            <origin xyz="0 0 -0.30455668033872185" rpy="0 0 0"/>
            <geometry>
                <box size="0.24555277287995952 0.2898213191802811 0.6091133606774437" />
            </geometry>
        </collision>
    </link>
    <joint name="body0_body1" type="revolute">
       <parent link="body0"/>
       <child  link="body1"/>
       <origin rpy="0 0 0" xyz="0.573865305763939 0 0.8690886319756386" />
     <axis xyz="0 1 0"/>
       <limit effort="0.0" lower="-3.14159" upper="3.14159" velocity="0.0"/>
    </joint>
    <joint name="body0_RightUpperLeg0" type="revolute">
       <parent link="body0"/>
       <child  link="RightUpperLeg0"/>
       <origin rpy="0 0 0" xyz="0.2869326528819695 -0.17118727419593893 0.8690886319756386" />
     <axis xyz="0 1 0"/>
       <limit effort="0.0" lower="-3.14159" upper="3.14159" velocity="0.0"/>
    </joint>
    <joint name="body0_LeftUpperLeg0" type="revolute">
       <parent link="body0"/>
       <child  link="LeftUpperLeg0"/>
       <origin rpy="0 0 0" xyz="0.2869326528819695 0.17118727419593893 0.8690886319756386" />
     <axis xyz="0 1 0"/>
       <limit effort="0.0" lower="-3.14159" upper="3.14159" velocity="0.0"/>
    </joint>
    <joint name="RightUpperLeg0_RightLowerLeg0" type="revolute">
       <parent link="RightUpperLeg0"/>
       <child  link="RightLowerLeg0"/>
       <origin rpy="0 0 0" xyz="0 -0.1548294037050802 -0.2599752712981949" />
     <axis xyz="0 1 0"/>
       <limit effort="0.0" lower="-3.14159" upper="3.14159" velocity="0.0"/>
    </joint>
    <joint name="LeftUpperLeg0_LeftLowerLeg0" type="revolute">
       <parent link="LeftUpperLeg0"/>
       <child  link="LeftLowerLeg0"/>
       <origin rpy="0 0 0" xyz="0.14632800192679904 0 0" />
     <axis xyz="0 1 0"/>
       <limit effort="0.0" lower="-3.14159" upper="3.14159" velocity="0.0"/>
    </joint>
    <joint name="body1_RightUpperLeg1" type="revolute">
       <parent link="body1"/>
       <child  link="RightUpperLeg1"/>
       <origin rpy="0 0 0" xyz="0.2869326528819695 -0.17118727419593893 0" />
     <axis xyz="0 1 0"/>
       <limit effort="0.0" lower="-3.14159" upper="3.14159" velocity="0.0"/>
    </joint>
    <joint name="body1_LeftUpperLeg1" type="revolute">
       <parent link="body1"/>
       <child  link="LeftUpperLeg1"/>
       <origin rpy="0 0 0" xyz="0.2869326528819695 0.17118727419593893 0" />
     <axis xyz="0 1 0"/>
       <limit effort="0.0" lower="-3.14159" upper="3.14159" velocity="0.0"/>
    </joint>
    <joint name="RightUpperLeg1_RightLowerLeg1" type="revolute">
       <parent link="RightUpperLeg1"/>
       <child  link="RightLowerLeg1"/>
       <origin rpy="0 0 0" xyz="0 -0.1548294037050802 -0.2599752712981949" />
     <axis xyz="0 1 0"/>
       <limit effort="0.0" lower="-3.14159" upper="3.14159" velocity="0.0"/>
    </joint>
    <joint name="LeftUpperLeg1_LeftLowerLeg1" type="revolute">
       <parent link="LeftUpperLeg1"/>
       <child  link="LeftLowerLeg1"/>
       <origin rpy="0 0 0" xyz="0 0.1548294037050802 -0.2599752712981949" />
     <axis xyz="0 1 0"/>
       <limit effort="0.0" lower="-3.14159" upper="3.14159" velocity="0.0"/>
    </joint>
</robot>