<robot name = "robot">
    <link name="body0">
        <inertial>
            <origin xyz="0.24022389390073223 0 0.9198318144938288" rpy="0 0 0"/>
            <mass value="1" />
            <inertia ixx="100" ixy="0" ixz="0" iyy="100" iyz="0" izz="100" />
        </inertial>
        <visual>
            <origin xyz="0.24022389390073223 0 0.9198318144938288" rpy="0 0 0"/>
            <geometry>
                <box size="0.48044778780146447 0.4561872870410456 0.40984104805171984" />
            </geometry>
            <material name="green">
                <color rgba="0 1.0 0 1.0"/>
            </material>
        </visual>
        <collision>
            <origin xyz="0.24022389390073223 0 0.9198318144938288" rpy="0 0 0"/>
            <geometry>
                <box size="0.48044778780146447 0.4561872870410456 0.40984104805171984" />
            </geometry>
        </collision>
    </link>
    <link name="RightUpperLeg0">
        <inertial>
            <origin xyz="0 -0.09336125420271316 -0.3434638103001115" rpy="0 0 0"/>
            <mass value="1" />
            <inertia ixx="100" ixy="0" ixz="0" iyy="100" iyz="0" izz="100" />
        </inertial>
        <visual>
            <origin xyz="0 -0.09336125420271316 -0.3434638103001115" rpy="0 0 0"/>
            <geometry>
                <box size="0.22782753114285767 0.1867225084054263 0.686927620600223" />
            </geometry>
            <material name="red">
                <color rgba="0 0 1.0 1.0"/>
            </material>
        </visual>
        <collision>
            <origin xyz="0 -0.09336125420271316 -0.3434638103001115" rpy="0 0 0"/>
            <geometry>
                <box size="0.22782753114285767 0.1867225084054263 0.686927620600223" />
            </geometry>
        </collision>
    </link>
    <link name="LeftUpperLeg0">
        <inertial>
            <origin xyz="0 0.09336125420271316 -0.3434638103001115" rpy="0 0 0"/>
            <mass value="1" />
            <inertia ixx="100" ixy="0" ixz="0" iyy="100" iyz="0" izz="100" />
        </inertial>
        <visual>
            <origin xyz="0 0.09336125420271316 -0.3434638103001115" rpy="0 0 0"/>
            <geometry>
                <box size="0.22782753114285767 0.1867225084054263 0.686927620600223" />
            </geometry>
            <material name="red">
                <color rgba="0 0 1.0 1.0"/>
            </material>
        </visual>
        <collision>
            <origin xyz="0 0.09336125420271316 -0.3434638103001115" rpy="0 0 0"/>
            <geometry>
                <box size="0.22782753114285767 0.1867225084054263 0.686927620600223" />
            </geometry>
        </collision>
    </link>
    <link name="RightLowerLeg0">
        <inertial>
            <origin xyz="0 0 -0.11645209694680286" rpy="0 0 0"/>
            <mass value="1" />
            <inertia ixx="100" ixy="0" ixz="0" iyy="100" iyz="0" izz="100" />
        </inertial>
        <visual>
            <origin xyz="0 0 -0.11645209694680286" rpy="0 0 0"/>
            <geometry>
                <box size="0.2001322136532011 0.1656403182459484 0.23290419389360573" />
            </geometry>
            <material name="red">
                <color rgba="0 0 1.0 1.0"/>
            </material>
        </visual>
        <collision>
            <origin xyz="0 0 -0.11645209694680286" rpy="0 0 0"/>
            <geometry>
                <box size="0.2001322136532011 0.1656403182459484 0.23290419389360573" />
            </geometry>
        </collision>
    </link>
    <link name="LeftLowerLeg0">
        <inertial>
            <origin xyz="0 0 -0.11645209694680286" rpy="0 0 0"/>
            <mass value="1" />
            <inertia ixx="100" ixy="0" ixz="0" iyy="100" iyz="0" izz="100" />
        </inertial>
        <visual>
            <origin xyz="0 0 -0.11645209694680286" rpy="0 0 0"/>
            <geometry>
                <box size="0.2001322136532011 0.1656403182459484 0.23290419389360573" />
            </geometry>
            <material name="green">
                <color rgba="0 1.0 0 1.0"/>
            </material>
        </visual>
        <collision>
            <origin xyz="0 0 -0.11645209694680286" rpy="0 0 0"/>
            <geometry>
                <box size="0.2001322136532011 0.1656403182459484 0.23290419389360573" />
            </geometry>
        </collision>
    </link>
    <link name="body1">
        <inertial>
            <origin xyz="0.24022389390073223 0 0" rpy="0 0 0"/>
            <mass value="1" />
            <inertia ixx="100" ixy="0" ixz="0" iyy="100" iyz="0" izz="100" />
        </inertial>
        <visual>
            <origin xyz="0.24022389390073223 0 0" rpy="0 0 0"/>
            <geometry>
                <box size="0.48044778780146447 0.4561872870410456 0.40984104805171984" />
            </geometry>
            <material name="red">
                <color rgba="0 0 1.0 1.0"/>
            </material>
        </visual>
        <collision>
            <origin xyz="0.24022389390073223 0 0" rpy="0 0 0"/>
            <geometry>
                <box size="0.48044778780146447 0.4561872870410456 0.40984104805171984" />
            </geometry>
        </collision>
    </link>
    <link name="RightUpperLeg1">
        <inertial>
            <origin xyz="0 -0.09336125420271316 -0.3434638103001115" rpy="0 0 0"/>
            <mass value="1" />
            <inertia ixx="100" ixy="0" ixz="0" iyy="100" iyz="0" izz="100" />
        </inertial>
        <visual>
            <origin xyz="0 -0.09336125420271316 -0.3434638103001115" rpy="0 0 0"/>
            <geometry>
                <box size="0.22782753114285767 0.1867225084054263 0.686927620600223" />
            </geometry>
            <material name="red">
                <color rgba="0 0 1.0 1.0"/>
            </material>
        </visual>
        <collision>
            <origin xyz="0 -0.09336125420271316 -0.3434638103001115" rpy="0 0 0"/>
            <geometry>
                <box size="0.22782753114285767 0.1867225084054263 0.686927620600223" />
            </geometry>
        </collision>
    </link>
    <link name="LeftUpperLeg1">
        <inertial>
            <origin xyz="0 0.09336125420271316 -0.3434638103001115" rpy="0 0 0"/>
            <mass value="1" />
            <inertia ixx="100" ixy="0" ixz="0" iyy="100" iyz="0" izz="100" />
        </inertial>
        <visual>
            <origin xyz="0 0.09336125420271316 -0.3434638103001115" rpy="0 0 0"/>
            <geometry>
                <box size="0.22782753114285767 0.1867225084054263 0.686927620600223" />
            </geometry>
            <material name="red">
                <color rgba="0 0 1.0 1.0"/>
            </material>
        </visual>
        <collision>
            <origin xyz="0 0.09336125420271316 -0.3434638103001115" rpy="0 0 0"/>
            <geometry>
                <box size="0.22782753114285767 0.1867225084054263 0.686927620600223" />
            </geometry>
        </collision>
    </link>
    <link name="RightLowerLeg1">
        <inertial>
            <origin xyz="0 0 -0.11645209694680286" rpy="0 0 0"/>
            <mass value="1" />
            <inertia ixx="100" ixy="0" ixz="0" iyy="100" iyz="0" izz="100" />
        </inertial>
        <visual>
            <origin xyz="0 0 -0.11645209694680286" rpy="0 0 0"/>
            <geometry>
                <box size="0.2001322136532011 0.1656403182459484 0.23290419389360573" />
            </geometry>
            <material name="green">
                <color rgba="0 1.0 0 1.0"/>
            </material>
        </visual>
        <collision>
            <origin xyz="0 0 -0.11645209694680286" rpy="0 0 0"/>
            <geometry>
                <box size="0.2001322136532011 0.1656403182459484 0.23290419389360573" />
            </geometry>
        </collision>
    </link>
    <link name="LeftLowerLeg1">
        <inertial>
            <origin xyz="0 0 -0.11645209694680286" rpy="0 0 0"/>
            <mass value="1" />
            <inertia ixx="100" ixy="0" ixz="0" iyy="100" iyz="0" izz="100" />
        </inertial>
        <visual>
            <origin xyz="0 0 -0.11645209694680286" rpy="0 0 0"/>
            <geometry>
                <box size="0.2001322136532011 0.1656403182459484 0.23290419389360573" />
            </geometry>
            <material name="red">
                <color rgba="0 0 1.0 1.0"/>
            </material>
        </visual>
        <collision>
            <origin xyz="0 0 -0.11645209694680286" rpy="0 0 0"/>
            <geometry>
                <box size="0.2001322136532011 0.1656403182459484 0.23290419389360573" />
            </geometry>
        </collision>
    </link>
    <joint name="body0_body1" type="revolute">
       <parent link="body0"/>
       <child  link="body1"/>
       <origin rpy="0 0 0" xyz="0.48044778780146447 0 0.9198318144938288" />
     <axis xyz="0 1 0"/>
       <limit effort="0.0" lower="-3.14159" upper="3.14159" velocity="0.0"/>
    </joint>
    <joint name="body0_RightUpperLeg0" type="revolute">
       <parent link="body0"/>
       <child  link="RightUpperLeg0"/>
       <origin rpy="0 0 0" xyz="0.24022389390073223 -0.2280936435205228 0.9198318144938288" />
     <axis xyz="0 1 0"/>
       <limit effort="0.0" lower="-3.14159" upper="3.14159" velocity="0.0"/>
    </joint>
    <joint name="body0_LeftUpperLeg0" type="revolute">
       <parent link="body0"/>
       <child  link="LeftUpperLeg0"/>
       <origin rpy="0 0 0" xyz="0.24022389390073223 0.2280936435205228 0.9198318144938288" />
     <axis xyz="0 1 0"/>
       <limit effort="0.0" lower="-3.14159" upper="3.14159" velocity="0.0"/>
    </joint>
    <joint name="RightUpperLeg0_RightLowerLeg0" type="revolute">
       <parent link="RightUpperLeg0"/>
       <child  link="RightLowerLeg0"/>
       <origin rpy="0 0 0" xyz="0 -0.09336125420271316 -0.686927620600223" />
     <axis xyz="0 1 0"/>
       <limit effort="0.0" lower="-3.14159" upper="3.14159" velocity="0.0"/>
    </joint>
    <joint name="LeftUpperLeg0_LeftLowerLeg0" type="revolute">
       <parent link="LeftUpperLeg0"/>
       <child  link="LeftLowerLeg0"/>
       <origin rpy="0 0 0" xyz="0.22782753114285767 0 0" />
     <axis xyz="0 1 0"/>
       <limit effort="0.0" lower="-3.14159" upper="3.14159" velocity="0.0"/>
    </joint>
    <joint name="body1_RightUpperLeg1" type="revolute">
       <parent link="body1"/>
       <child  link="RightUpperLeg1"/>
       <origin rpy="0 0 0" xyz="0.24022389390073223 -0.2280936435205228 0" />
     <axis xyz="0 1 0"/>
       <limit effort="0.0" lower="-3.14159" upper="3.14159" velocity="0.0"/>
    </joint>
    <joint name="body1_LeftUpperLeg1" type="revolute">
       <parent link="body1"/>
       <child  link="LeftUpperLeg1"/>
       <origin rpy="0 0 0" xyz="0.24022389390073223 0.2280936435205228 0" />
     <axis xyz="0 1 0"/>
       <limit effort="0.0" lower="-3.14159" upper="3.14159" velocity="0.0"/>
    </joint>
    <joint name="RightUpperLeg1_RightLowerLeg1" type="revolute">
       <parent link="RightUpperLeg1"/>
       <child  link="RightLowerLeg1"/>
       <origin rpy="0 0 0" xyz="0 -0.09336125420271316 -0.686927620600223" />
     <axis xyz="0 1 0"/>
       <limit effort="0.0" lower="-3.14159" upper="3.14159" velocity="0.0"/>
    </joint>
    <joint name="LeftUpperLeg1_LeftLowerLeg1" type="revolute">
       <parent link="LeftUpperLeg1"/>
       <child  link="LeftLowerLeg1"/>
       <origin rpy="0 0 0" xyz="0 0.09336125420271316 -0.686927620600223" />
     <axis xyz="0 1 0"/>
       <limit effort="0.0" lower="-3.14159" upper="3.14159" velocity="0.0"/>
    </joint>
</robot>