<robot name = "robot">
    <link name="body0">
        <inertial>
            <origin xyz="0.25280693895738104 0 1.0016908094097525" rpy="0 0 0"/>
            <mass value="1" />
            <inertia ixx="100" ixy="0" ixz="0" iyy="100" iyz="0" izz="100" />
        </inertial>
        <visual>
            <origin xyz="0.25280693895738104 0 1.0016908094097525" rpy="0 0 0"/>
            <geometry>
                <box size="0.5056138779147621 0.28706236576520683 0.13760005610216533" />
            </geometry>
            <material name="green">
                <color rgba="0 1.0 0 1.0"/>
            </material>
        </visual>
        <collision>
            <origin xyz="0.25280693895738104 0 1.0016908094097525" rpy="0 0 0"/>
            <geometry>
                <box size="0.5056138779147621 0.28706236576520683 0.13760005610216533" />
            </geometry>
        </collision>
    </link>
    <link name="RightUpperLeg0">
        <inertial>
            <origin xyz="0 -0.0595654698245619 -0.3102602889523457" rpy="0 0 0"/>
            <mass value="1" />
            <inertia ixx="100" ixy="0" ixz="0" iyy="100" iyz="0" izz="100" />
        </inertial>
        <visual>
            <origin xyz="0 -0.0595654698245619 -0.3102602889523457" rpy="0 0 0"/>
            <geometry>
                <box size="0.3281735454530538 0.1191309396491238 0.6205205779046914" />
            </geometry>
            <material name="green">
                <color rgba="0 1.0 0 1.0"/>
            </material>
        </visual>
        <collision>
            <origin xyz="0 -0.0595654698245619 -0.3102602889523457" rpy="0 0 0"/>
            <geometry>
                <box size="0.3281735454530538 0.1191309396491238 0.6205205779046914" />
            </geometry>
        </collision>
    </link>
    <link name="LeftUpperLeg0">
        <inertial>
            <origin xyz="0 0.0595654698245619 -0.3102602889523457" rpy="0 0 0"/>
            <mass value="1" />
            <inertia ixx="100" ixy="0" ixz="0" iyy="100" iyz="0" izz="100" />
        </inertial>
        <visual>
            <origin xyz="0 0.0595654698245619 -0.3102602889523457" rpy="0 0 0"/>
            <geometry>
                <box size="0.3281735454530538 0.1191309396491238 0.6205205779046914" />
            </geometry>
            <material name="green">
                <color rgba="0 1.0 0 1.0"/>
            </material>
        </visual>
        <collision>
            <origin xyz="0 0.0595654698245619 -0.3102602889523457" rpy="0 0 0"/>
            <geometry>
                <box size="0.3281735454530538 0.1191309396491238 0.6205205779046914" />
            </geometry>
        </collision>
    </link>
    <link name="RightLowerLeg0">
        <inertial>
            <origin xyz="0 0 -0.1905851157525305" rpy="0 0 0"/>
            <mass value="1" />
            <inertia ixx="100" ixy="0" ixz="0" iyy="100" iyz="0" izz="100" />
        </inertial>
        <visual>
            <origin xyz="0 0 -0.1905851157525305" rpy="0 0 0"/>
            <geometry>
                <box size="0.30779012326207505 0.23377013287434628 0.381170231505061" />
            </geometry>
            <material name="red">
                <color rgba="0 0 1.0 1.0"/>
            </material>
        </visual>
        <collision>
            <origin xyz="0 0 -0.1905851157525305" rpy="0 0 0"/>
            <geometry>
                <box size="0.30779012326207505 0.23377013287434628 0.381170231505061" />
            </geometry>
        </collision>
    </link>
    <link name="LeftLowerLeg0">
        <inertial>
            <origin xyz="0 0 -0.1905851157525305" rpy="0 0 0"/>
            <mass value="1" />
            <inertia ixx="100" ixy="0" ixz="0" iyy="100" iyz="0" izz="100" />
        </inertial>
        <visual>
            <origin xyz="0 0 -0.1905851157525305" rpy="0 0 0"/>
            <geometry>
                <box size="0.30779012326207505 0.23377013287434628 0.381170231505061" />
            </geometry>
            <material name="green">
                <color rgba="0 1.0 0 1.0"/>
            </material>
        </visual>
        <collision>
            <origin xyz="0 0 -0.1905851157525305" rpy="0 0 0"/>
            <geometry>
                <box size="0.30779012326207505 0.23377013287434628 0.381170231505061" />
            </geometry>
        </collision>
    </link>
    <link name="body1">
        <inertial>
            <origin xyz="0.25280693895738104 0 0" rpy="0 0 0"/>
            <mass value="1" />
            <inertia ixx="100" ixy="0" ixz="0" iyy="100" iyz="0" izz="100" />
        </inertial>
        <visual>
            <origin xyz="0.25280693895738104 0 0" rpy="0 0 0"/>
            <geometry>
                <box size="0.5056138779147621 0.28706236576520683 0.13760005610216533" />
            </geometry>
            <material name="green">
                <color rgba="0 1.0 0 1.0"/>
            </material>
        </visual>
        <collision>
            <origin xyz="0.25280693895738104 0 0" rpy="0 0 0"/>
            <geometry>
                <box size="0.5056138779147621 0.28706236576520683 0.13760005610216533" />
            </geometry>
        </collision>
    </link>
    <link name="RightUpperLeg1">
        <inertial>
            <origin xyz="0 -0.0595654698245619 -0.3102602889523457" rpy="0 0 0"/>
            <mass value="1" />
            <inertia ixx="100" ixy="0" ixz="0" iyy="100" iyz="0" izz="100" />
        </inertial>
        <visual>
            <origin xyz="0 -0.0595654698245619 -0.3102602889523457" rpy="0 0 0"/>
            <geometry>
                <box size="0.3281735454530538 0.1191309396491238 0.6205205779046914" />
            </geometry>
            <material name="green">
                <color rgba="0 1.0 0 1.0"/>
            </material>
        </visual>
        <collision>
            <origin xyz="0 -0.0595654698245619 -0.3102602889523457" rpy="0 0 0"/>
            <geometry>
                <box size="0.3281735454530538 0.1191309396491238 0.6205205779046914" />
            </geometry>
        </collision>
    </link>
    <link name="LeftUpperLeg1">
        <inertial>
            <origin xyz="0 0.0595654698245619 -0.3102602889523457" rpy="0 0 0"/>
            <mass value="1" />
            <inertia ixx="100" ixy="0" ixz="0" iyy="100" iyz="0" izz="100" />
        </inertial>
        <visual>
            <origin xyz="0 0.0595654698245619 -0.3102602889523457" rpy="0 0 0"/>
            <geometry>
                <box size="0.3281735454530538 0.1191309396491238 0.6205205779046914" />
            </geometry>
            <material name="green">
                <color rgba="0 1.0 0 1.0"/>
            </material>
        </visual>
        <collision>
            <origin xyz="0 0.0595654698245619 -0.3102602889523457" rpy="0 0 0"/>
            <geometry>
                <box size="0.3281735454530538 0.1191309396491238 0.6205205779046914" />
            </geometry>
        </collision>
    </link>
    <link name="RightLowerLeg1">
        <inertial>
            <origin xyz="0 0 -0.1905851157525305" rpy="0 0 0"/>
            <mass value="1" />
            <inertia ixx="100" ixy="0" ixz="0" iyy="100" iyz="0" izz="100" />
        </inertial>
        <visual>
            <origin xyz="0 0 -0.1905851157525305" rpy="0 0 0"/>
            <geometry>
                <box size="0.30779012326207505 0.23377013287434628 0.381170231505061" />
            </geometry>
            <material name="red">
                <color rgba="0 0 1.0 1.0"/>
            </material>
        </visual>
        <collision>
            <origin xyz="0 0 -0.1905851157525305" rpy="0 0 0"/>
            <geometry>
                <box size="0.30779012326207505 0.23377013287434628 0.381170231505061" />
            </geometry>
        </collision>
    </link>
    <link name="LeftLowerLeg1">
        <inertial>
            <origin xyz="0 0 -0.1905851157525305" rpy="0 0 0"/>
            <mass value="1" />
            <inertia ixx="100" ixy="0" ixz="0" iyy="100" iyz="0" izz="100" />
        </inertial>
        <visual>
            <origin xyz="0 0 -0.1905851157525305" rpy="0 0 0"/>
            <geometry>
                <box size="0.30779012326207505 0.23377013287434628 0.381170231505061" />
            </geometry>
            <material name="red">
                <color rgba="0 0 1.0 1.0"/>
            </material>
        </visual>
        <collision>
            <origin xyz="0 0 -0.1905851157525305" rpy="0 0 0"/>
            <geometry>
                <box size="0.30779012326207505 0.23377013287434628 0.381170231505061" />
            </geometry>
        </collision>
    </link>
    <link name="body2">
        <inertial>
            <origin xyz="0.25280693895738104 0 0" rpy="0 0 0"/>
            <mass value="1" />
            <inertia ixx="100" ixy="0" ixz="0" iyy="100" iyz="0" izz="100" />
        </inertial>
        <visual>
            <origin xyz="0.25280693895738104 0 0" rpy="0 0 0"/>
            <geometry>
                <box size="0.5056138779147621 0.28706236576520683 0.13760005610216533" />
            </geometry>
            <material name="red">
                <color rgba="0 0 1.0 1.0"/>
            </material>
        </visual>
        <collision>
            <origin xyz="0.25280693895738104 0 0" rpy="0 0 0"/>
            <geometry>
                <box size="0.5056138779147621 0.28706236576520683 0.13760005610216533" />
            </geometry>
        </collision>
    </link>
    <link name="RightUpperLeg2">
        <inertial>
            <origin xyz="0 -0.0595654698245619 -0.3102602889523457" rpy="0 0 0"/>
            <mass value="1" />
            <inertia ixx="100" ixy="0" ixz="0" iyy="100" iyz="0" izz="100" />
        </inertial>
        <visual>
            <origin xyz="0 -0.0595654698245619 -0.3102602889523457" rpy="0 0 0"/>
            <geometry>
                <box size="0.3281735454530538 0.1191309396491238 0.6205205779046914" />
            </geometry>
            <material name="red">
                <color rgba="0 0 1.0 1.0"/>
            </material>
        </visual>
        <collision>
            <origin xyz="0 -0.0595654698245619 -0.3102602889523457" rpy="0 0 0"/>
            <geometry>
                <box size="0.3281735454530538 0.1191309396491238 0.6205205779046914" />
            </geometry>
        </collision>
    </link>
    <link name="LeftUpperLeg2">
        <inertial>
            <origin xyz="0 0.0595654698245619 -0.3102602889523457" rpy="0 0 0"/>
            <mass value="1" />
            <inertia ixx="100" ixy="0" ixz="0" iyy="100" iyz="0" izz="100" />
        </inertial>
        <visual>
            <origin xyz="0 0.0595654698245619 -0.3102602889523457" rpy="0 0 0"/>
            <geometry>
                <box size="0.3281735454530538 0.1191309396491238 0.6205205779046914" />
            </geometry>
            <material name="green">
                <color rgba="0 1.0 0 1.0"/>
            </material>
        </visual>
        <collision>
            <origin xyz="0 0.0595654698245619 -0.3102602889523457" rpy="0 0 0"/>
            <geometry>
                <box size="0.3281735454530538 0.1191309396491238 0.6205205779046914" />
            </geometry>
        </collision>
    </link>
    <link name="RightLowerLeg2">
        <inertial>
            <origin xyz="0 0 -0.1905851157525305" rpy="0 0 0"/>
            <mass value="1" />
            <inertia ixx="100" ixy="0" ixz="0" iyy="100" iyz="0" izz="100" />
        </inertial>
        <visual>
            <origin xyz="0 0 -0.1905851157525305" rpy="0 0 0"/>
            <geometry>
                <box size="0.30779012326207505 0.23377013287434628 0.381170231505061" />
            </geometry>
            <material name="green">
                <color rgba="0 1.0 0 1.0"/>
            </material>
        </visual>
        <collision>
            <origin xyz="0 0 -0.1905851157525305" rpy="0 0 0"/>
            <geometry>
                <box size="0.30779012326207505 0.23377013287434628 0.381170231505061" />
            </geometry>
        </collision>
    </link>
    <link name="LeftLowerLeg2">
        <inertial>
            <origin xyz="0 0 -0.1905851157525305" rpy="0 0 0"/>
            <mass value="1" />
            <inertia ixx="100" ixy="0" ixz="0" iyy="100" iyz="0" izz="100" />
        </inertial>
        <visual>
            <origin xyz="0 0 -0.1905851157525305" rpy="0 0 0"/>
            <geometry>
                <box size="0.30779012326207505 0.23377013287434628 0.381170231505061" />
            </geometry>
            <material name="red">
                <color rgba="0 0 1.0 1.0"/>
            </material>
        </visual>
        <collision>
            <origin xyz="0 0 -0.1905851157525305" rpy="0 0 0"/>
            <geometry>
                <box size="0.30779012326207505 0.23377013287434628 0.381170231505061" />
            </geometry>
        </collision>
    </link>
    <link name="body3">
        <inertial>
            <origin xyz="0.25280693895738104 0 0" rpy="0 0 0"/>
            <mass value="1" />
            <inertia ixx="100" ixy="0" ixz="0" iyy="100" iyz="0" izz="100" />
        </inertial>
        <visual>
            <origin xyz="0.25280693895738104 0 0" rpy="0 0 0"/>
            <geometry>
                <box size="0.5056138779147621 0.28706236576520683 0.13760005610216533" />
            </geometry>
            <material name="red">
                <color rgba="0 0 1.0 1.0"/>
            </material>
        </visual>
        <collision>
            <origin xyz="0.25280693895738104 0 0" rpy="0 0 0"/>
            <geometry>
                <box size="0.5056138779147621 0.28706236576520683 0.13760005610216533" />
            </geometry>
        </collision>
    </link>
    <link name="RightUpperLeg3">
        <inertial>
            <origin xyz="0 -0.0595654698245619 -0.3102602889523457" rpy="0 0 0"/>
            <mass value="1" />
            <inertia ixx="100" ixy="0" ixz="0" iyy="100" iyz="0" izz="100" />
        </inertial>
        <visual>
            <origin xyz="0 -0.0595654698245619 -0.3102602889523457" rpy="0 0 0"/>
            <geometry>
                <box size="0.3281735454530538 0.1191309396491238 0.6205205779046914" />
            </geometry>
            <material name="green">
                <color rgba="0 1.0 0 1.0"/>
            </material>
        </visual>
        <collision>
            <origin xyz="0 -0.0595654698245619 -0.3102602889523457" rpy="0 0 0"/>
            <geometry>
                <box size="0.3281735454530538 0.1191309396491238 0.6205205779046914" />
            </geometry>
        </collision>
    </link>
    <link name="LeftUpperLeg3">
        <inertial>
            <origin xyz="0 0.0595654698245619 -0.3102602889523457" rpy="0 0 0"/>
            <mass value="1" />
            <inertia ixx="100" ixy="0" ixz="0" iyy="100" iyz="0" izz="100" />
        </inertial>
        <visual>
            <origin xyz="0 0.0595654698245619 -0.3102602889523457" rpy="0 0 0"/>
            <geometry>
                <box size="0.3281735454530538 0.1191309396491238 0.6205205779046914" />
            </geometry>
            <material name="green">
                <color rgba="0 1.0 0 1.0"/>
            </material>
        </visual>
        <collision>
            <origin xyz="0 0.0595654698245619 -0.3102602889523457" rpy="0 0 0"/>
            <geometry>
                <box size="0.3281735454530538 0.1191309396491238 0.6205205779046914" />
            </geometry>
        </collision>
    </link>
    <link name="RightLowerLeg3">
        <inertial>
            <origin xyz="0 0 -0.1905851157525305" rpy="0 0 0"/>
            <mass value="1" />
            <inertia ixx="100" ixy="0" ixz="0" iyy="100" iyz="0" izz="100" />
        </inertial>
        <visual>
            <origin xyz="0 0 -0.1905851157525305" rpy="0 0 0"/>
            <geometry>
                <box size="0.30779012326207505 0.23377013287434628 0.381170231505061" />
            </geometry>
            <material name="red">
                <color rgba="0 0 1.0 1.0"/>
            </material>
        </visual>
        <collision>
            <origin xyz="0 0 -0.1905851157525305" rpy="0 0 0"/>
            <geometry>
                <box size="0.30779012326207505 0.23377013287434628 0.381170231505061" />
            </geometry>
        </collision>
    </link>
    <link name="LeftLowerLeg3">
        <inertial>
            <origin xyz="0 0 -0.1905851157525305" rpy="0 0 0"/>
            <mass value="1" />
            <inertia ixx="100" ixy="0" ixz="0" iyy="100" iyz="0" izz="100" />
        </inertial>
        <visual>
            <origin xyz="0 0 -0.1905851157525305" rpy="0 0 0"/>
            <geometry>
                <box size="0.30779012326207505 0.23377013287434628 0.381170231505061" />
            </geometry>
            <material name="red">
                <color rgba="0 0 1.0 1.0"/>
            </material>
        </visual>
        <collision>
            <origin xyz="0 0 -0.1905851157525305" rpy="0 0 0"/>
            <geometry>
                <box size="0.30779012326207505 0.23377013287434628 0.381170231505061" />
            </geometry>
        </collision>
    </link>
    <joint name="body0_body1" type="revolute">
       <parent link="body0"/>
       <child  link="body1"/>
       <origin rpy="0 0 0" xyz="0.5056138779147621 0 1.0016908094097525" />
     <axis xyz="0 1 0"/>
       <limit effort="0.0" lower="-3.14159" upper="3.14159" velocity="0.0"/>
    </joint>
    <joint name="body0_RightUpperLeg0" type="revolute">
       <parent link="body0"/>
       <child  link="RightUpperLeg0"/>
       <origin rpy="0 0 0" xyz="0.25280693895738104 -0.14353118288260341 1.0016908094097525" />
     <axis xyz="0 1 0"/>
       <limit effort="0.0" lower="-3.14159" upper="3.14159" velocity="0.0"/>
    </joint>
    <joint name="body0_LeftUpperLeg0" type="revolute">
       <parent link="body0"/>
       <child  link="LeftUpperLeg0"/>
       <origin rpy="0 0 0" xyz="0.25280693895738104 0.14353118288260341 1.0016908094097525" />
     <axis xyz="0 1 0"/>
       <limit effort="0.0" lower="-3.14159" upper="3.14159" velocity="0.0"/>
    </joint>
    <joint name="RightUpperLeg0_RightLowerLeg0" type="revolute">
       <parent link="RightUpperLeg0"/>
       <child  link="RightLowerLeg0"/>
       <origin rpy="0 0 0" xyz="0 -0.0595654698245619 -0.6205205779046914" />
     <axis xyz="0 1 0"/>
       <limit effort="0.0" lower="-3.14159" upper="3.14159" velocity="0.0"/>
    </joint>
    <joint name="LeftUpperLeg0_LeftLowerLeg0" type="revolute">
       <parent link="LeftUpperLeg0"/>
       <child  link="LeftLowerLeg0"/>
       <origin rpy="0 0 0" xyz="0 0.0595654698245619 -0.6205205779046914" />
     <axis xyz="0 1 0"/>
       <limit effort="0.0" lower="-3.14159" upper="3.14159" velocity="0.0"/>
    </joint>
    <joint name="body1_body2" type="revolute">
       <parent link="body1"/>
       <child  link="body2"/>
       <origin rpy="0 0 0" xyz="0.5056138779147621 0 0" />
     <axis xyz="0 1 0"/>
       <limit effort="0.0" lower="-3.14159" upper="3.14159" velocity="0.0"/>
    </joint>
    <joint name="body1_RightUpperLeg1" type="revolute">
       <parent link="body1"/>
       <child  link="RightUpperLeg1"/>
       <origin rpy="0 0 0" xyz="0.25280693895738104 -0.14353118288260341 0" />
     <axis xyz="0 1 0"/>
       <limit effort="0.0" lower="-3.14159" upper="3.14159" velocity="0.0"/>
    </joint>
    <joint name="body1_LeftUpperLeg1" type="revolute">
       <parent link="body1"/>
       <child  link="LeftUpperLeg1"/>
       <origin rpy="0 0 0" xyz="0.25280693895738104 0.14353118288260341 0" />
     <axis xyz="0 1 0"/>
       <limit effort="0.0" lower="-3.14159" upper="3.14159" velocity="0.0"/>
    </joint>
    <joint name="RightUpperLeg1_RightLowerLeg1" type="revolute">
       <parent link="RightUpperLeg1"/>
       <child  link="RightLowerLeg1"/>
       <origin rpy="0 0 0" xyz="0 -0.0595654698245619 -0.6205205779046914" />
     <axis xyz="0 1 0"/>
       <limit effort="0.0" lower="-3.14159" upper="3.14159" velocity="0.0"/>
    </joint>
    <joint name="LeftUpperLeg1_LeftLowerLeg1" type="revolute">
       <parent link="LeftUpperLeg1"/>
       <child  link="LeftLowerLeg1"/>
       <origin rpy="0 0 0" xyz="0 0.0595654698245619 -0.6205205779046914" />
     <axis xyz="0 1 0"/>
       <limit effort="0.0" lower="-3.14159" upper="3.14159" velocity="0.0"/>
    </joint>
    <joint name="body2_body3" type="revolute">
       <parent link="body2"/>
       <child  link="body3"/>
       <origin rpy="0 0 0" xyz="0.5056138779147621 0 0" />
     <axis xyz="0 1 0"/>
       <limit effort="0.0" lower="-3.14159" upper="3.14159" velocity="0.0"/>
    </joint>
    <joint name="body2_RightUpperLeg2" type="revolute">
       <parent link="body2"/>
       <child  link="RightUpperLeg2"/>
       <origin rpy="0 0 0" xyz="0.25280693895738104 -0.14353118288260341 0" />
     <axis xyz="0 1 0"/>
       <limit effort="0.0" lower="-3.14159" upper="3.14159" velocity="0.0"/>
    </joint>
    <joint name="body2_LeftUpperLeg2" type="revolute">
       <parent link="body2"/>
       <child  link="LeftUpperLeg2"/>
       <origin rpy="0 0 0" xyz="0.25280693895738104 0.14353118288260341 0" />
     <axis xyz="0 1 0"/>
       <limit effort="0.0" lower="-3.14159" upper="3.14159" velocity="0.0"/>
    </joint>
    <joint name="RightUpperLeg2_RightLowerLeg2" type="revolute">
       <parent link="RightUpperLeg2"/>
       <child  link="RightLowerLeg2"/>
       <origin rpy="0 0 0" xyz="0 -0.0595654698245619 -0.6205205779046914" />
     <axis xyz="0 1 0"/>
       <limit effort="0.0" lower="-3.14159" upper="3.14159" velocity="0.0"/>
    </joint>
    <joint name="LeftUpperLeg2_LeftLowerLeg2" type="revolute">
       <parent link="LeftUpperLeg2"/>
       <child  link="LeftLowerLeg2"/>
       <origin rpy="0 0 0" xyz="0.3281735454530538 0 0" />
     <axis xyz="0 1 0"/>
       <limit effort="0.0" lower="-3.14159" upper="3.14159" velocity="0.0"/>
    </joint>
    <joint name="body3_RightUpperLeg3" type="revolute">
       <parent link="body3"/>
       <child  link="RightUpperLeg3"/>
       <origin rpy="0 0 0" xyz="0.25280693895738104 -0.14353118288260341 0" />
     <axis xyz="0 1 0"/>
       <limit effort="0.0" lower="-3.14159" upper="3.14159" velocity="0.0"/>
    </joint>
    <joint name="body3_LeftUpperLeg3" type="revolute">
       <parent link="body3"/>
       <child  link="LeftUpperLeg3"/>
       <origin rpy="0 0 0" xyz="0.25280693895738104 0.14353118288260341 0" />
     <axis xyz="0 1 0"/>
       <limit effort="0.0" lower="-3.14159" upper="3.14159" velocity="0.0"/>
    </joint>
    <joint name="RightUpperLeg3_RightLowerLeg3" type="revolute">
       <parent link="RightUpperLeg3"/>
       <child  link="RightLowerLeg3"/>
       <origin rpy="0 0 0" xyz="0 -0.0595654698245619 -0.6205205779046914" />
     <axis xyz="0 1 0"/>
       <limit effort="0.0" lower="-3.14159" upper="3.14159" velocity="0.0"/>
    </joint>
    <joint name="LeftUpperLeg3_LeftLowerLeg3" type="revolute">
       <parent link="LeftUpperLeg3"/>
       <child  link="LeftLowerLeg3"/>
       <origin rpy="0 0 0" xyz="0 0.0595654698245619 -0.6205205779046914" />
     <axis xyz="0 1 0"/>
       <limit effort="0.0" lower="-3.14159" upper="3.14159" velocity="0.0"/>
    </joint>
</robot>