<robot name = "robot">
    <link name="body0">
        <inertial>
            <origin xyz="0.2644864044056892 0 0.8344408530464681" rpy="0 0 0"/>
            <mass value="1" />
            <inertia ixx="100" ixy="0" ixz="0" iyy="100" iyz="0" izz="100" />
        </inertial>
        <visual>
            <origin xyz="0.2644864044056892 0 0.8344408530464681" rpy="0 0 0"/>
            <geometry>
                <box size="0.5289728088113784 0.5236258693920627 0.41178184839298615" />
            </geometry>
            <material name="green">
                <color rgba="0 1.0 0 1.0"/>
            </material>
        </visual>
        <collision>
            <origin xyz="0.2644864044056892 0 0.8344408530464681" rpy="0 0 0"/>
            <geometry>
                <box size="0.5289728088113784 0.5236258693920627 0.41178184839298615" />
            </geometry>
        </collision>
    </link>
    <link name="RightUpperLeg0">
        <inertial>
            <origin xyz="0 -0.09463019098167086 -0.1141782443293608" rpy="0 0 0"/>
            <mass value="1" />
            <inertia ixx="100" ixy="0" ixz="0" iyy="100" iyz="0" izz="100" />
        </inertial>
        <visual>
            <origin xyz="0 -0.09463019098167086 -0.1141782443293608" rpy="0 0 0"/>
            <geometry>
                <box size="0.21531451218780998 0.18926038196334172 0.2283564886587216" />
            </geometry>
            <material name="green">
                <color rgba="0 1.0 0 1.0"/>
            </material>
        </visual>
        <collision>
            <origin xyz="0 -0.09463019098167086 -0.1141782443293608" rpy="0 0 0"/>
            <geometry>
                <box size="0.21531451218780998 0.18926038196334172 0.2283564886587216" />
            </geometry>
        </collision>
    </link>
    <link name="LeftUpperLeg0">
        <inertial>
            <origin xyz="0 0.09463019098167086 -0.1141782443293608" rpy="0 0 0"/>
            <mass value="1" />
            <inertia ixx="100" ixy="0" ixz="0" iyy="100" iyz="0" izz="100" />
        </inertial>
        <visual>
            <origin xyz="0 0.09463019098167086 -0.1141782443293608" rpy="0 0 0"/>
            <geometry>
                <box size="0.21531451218780998 0.18926038196334172 0.2283564886587216" />
            </geometry>
            <material name="red">
                <color rgba="0 0 1.0 1.0"/>
            </material>
        </visual>
        <collision>
            <origin xyz="0 0.09463019098167086 -0.1141782443293608" rpy="0 0 0"/>
            <geometry>
                <box size="0.21531451218780998 0.18926038196334172 0.2283564886587216" />
            </geometry>
        </collision>
    </link>
    <link name="RightLowerLeg0">
        <inertial>
            <origin xyz="0 0 -0.30304218219387324" rpy="0 0 0"/>
            <mass value="1" />
            <inertia ixx="100" ixy="0" ixz="0" iyy="100" iyz="0" izz="100" />
        </inertial>
        <visual>
            <origin xyz="0 0 -0.30304218219387324" rpy="0 0 0"/>
            <geometry>
                <box size="0.18179688837403396 0.243299535196405 0.6060843643877465" />
            </geometry>
            <material name="red">
                <color rgba="0 0 1.0 1.0"/>
            </material>
        </visual>
        <collision>
            <origin xyz="0 0 -0.30304218219387324" rpy="0 0 0"/>
            <geometry>
                <box size="0.18179688837403396 0.243299535196405 0.6060843643877465" />
            </geometry>
        </collision>
    </link>
    <link name="LeftLowerLeg0">
        <inertial>
            <origin xyz="0 0 -0.30304218219387324" rpy="0 0 0"/>
            <mass value="1" />
            <inertia ixx="100" ixy="0" ixz="0" iyy="100" iyz="0" izz="100" />
        </inertial>
        <visual>
            <origin xyz="0 0 -0.30304218219387324" rpy="0 0 0"/>
            <geometry>
                <box size="0.18179688837403396 0.243299535196405 0.6060843643877465" />
            </geometry>
            <material name="red">
                <color rgba="0 0 1.0 1.0"/>
            </material>
        </visual>
        <collision>
            <origin xyz="0 0 -0.30304218219387324" rpy="0 0 0"/>
            <geometry>
                <box size="0.18179688837403396 0.243299535196405 0.6060843643877465" />
            </geometry>
        </collision>
    </link>
    <link name="body1">
        <inertial>
            <origin xyz="0.2644864044056892 0 0" rpy="0 0 0"/>
            <mass value="1" />
            <inertia ixx="100" ixy="0" ixz="0" iyy="100" iyz="0" izz="100" />
        </inertial>
        <visual>
            <origin xyz="0.2644864044056892 0 0" rpy="0 0 0"/>
            <geometry>
                <box size="0.5289728088113784 0.5236258693920627 0.41178184839298615" />
            </geometry>
            <material name="red">
                <color rgba="0 0 1.0 1.0"/>
            </material>
        </visual>
        <collision>
            <origin xyz="0.2644864044056892 0 0" rpy="0 0 0"/>
            <geometry>
                <box size="0.5289728088113784 0.5236258693920627 0.41178184839298615" />
            </geometry>
        </collision>
    </link>
    <link name="RightUpperLeg1">
        <inertial>
            <origin xyz="0 -0.09463019098167086 -0.1141782443293608" rpy="0 0 0"/>
            <mass value="1" />
            <inertia ixx="100" ixy="0" ixz="0" iyy="100" iyz="0" izz="100" />
        </inertial>
        <visual>
            <origin xyz="0 -0.09463019098167086 -0.1141782443293608" rpy="0 0 0"/>
            <geometry>
                <box size="0.21531451218780998 0.18926038196334172 0.2283564886587216" />
            </geometry>
            <material name="green">
                <color rgba="0 1.0 0 1.0"/>
            </material>
        </visual>
        <collision>
            <origin xyz="0 -0.09463019098167086 -0.1141782443293608" rpy="0 0 0"/>
            <geometry>
                <box size="0.21531451218780998 0.18926038196334172 0.2283564886587216" />
            </geometry>
        </collision>
    </link>
    <link name="LeftUpperLeg1">
        <inertial>
            <origin xyz="0 0.09463019098167086 -0.1141782443293608" rpy="0 0 0"/>
            <mass value="1" />
            <inertia ixx="100" ixy="0" ixz="0" iyy="100" iyz="0" izz="100" />
        </inertial>
        <visual>
            <origin xyz="0 0.09463019098167086 -0.1141782443293608" rpy="0 0 0"/>
            <geometry>
                <box size="0.21531451218780998 0.18926038196334172 0.2283564886587216" />
            </geometry>
            <material name="red">
                <color rgba="0 0 1.0 1.0"/>
            </material>
        </visual>
        <collision>
            <origin xyz="0 0.09463019098167086 -0.1141782443293608" rpy="0 0 0"/>
            <geometry>
                <box size="0.21531451218780998 0.18926038196334172 0.2283564886587216" />
            </geometry>
        </collision>
    </link>
    <link name="RightLowerLeg1">
        <inertial>
            <origin xyz="0 0 -0.30304218219387324" rpy="0 0 0"/>
            <mass value="1" />
            <inertia ixx="100" ixy="0" ixz="0" iyy="100" iyz="0" izz="100" />
        </inertial>
        <visual>
            <origin xyz="0 0 -0.30304218219387324" rpy="0 0 0"/>
            <geometry>
                <box size="0.18179688837403396 0.243299535196405 0.6060843643877465" />
            </geometry>
            <material name="green">
                <color rgba="0 1.0 0 1.0"/>
            </material>
        </visual>
        <collision>
            <origin xyz="0 0 -0.30304218219387324" rpy="0 0 0"/>
            <geometry>
                <box size="0.18179688837403396 0.243299535196405 0.6060843643877465" />
            </geometry>
        </collision>
    </link>
    <link name="LeftLowerLeg1">
        <inertial>
            <origin xyz="0 0 -0.30304218219387324" rpy="0 0 0"/>
            <mass value="1" />
            <inertia ixx="100" ixy="0" ixz="0" iyy="100" iyz="0" izz="100" />
        </inertial>
        <visual>
            <origin xyz="0 0 -0.30304218219387324" rpy="0 0 0"/>
            <geometry>
                <box size="0.18179688837403396 0.243299535196405 0.6060843643877465" />
            </geometry>
            <material name="red">
                <color rgba="0 0 1.0 1.0"/>
            </material>
        </visual>
        <collision>
            <origin xyz="0 0 -0.30304218219387324" rpy="0 0 0"/>
            <geometry>
                <box size="0.18179688837403396 0.243299535196405 0.6060843643877465" />
            </geometry>
        </collision>
    </link>
    <joint name="body0_body1" type="revolute">
       <parent link="body0"/>
       <child  link="body1"/>
       <origin rpy="0 0 0" xyz="0.5289728088113784 0 0.8344408530464681" />
     <axis xyz="0 1 0"/>
       <limit effort="0.0" lower="-3.14159" upper="3.14159" velocity="0.0"/>
    </joint>
    <joint name="body0_RightUpperLeg0" type="revolute">
       <parent link="body0"/>
       <child  link="RightUpperLeg0"/>
       <origin rpy="0 0 0" xyz="0.2644864044056892 -0.26181293469603134 0.8344408530464681" />
     <axis xyz="0 1 0"/>
       <limit effort="0.0" lower="-3.14159" upper="3.14159" velocity="0.0"/>
    </joint>
    <joint name="body0_LeftUpperLeg0" type="revolute">
       <parent link="body0"/>
       <child  link="LeftUpperLeg0"/>
       <origin rpy="0 0 0" xyz="0.2644864044056892 0.26181293469603134 0.8344408530464681" />
     <axis xyz="0 1 0"/>
       <limit effort="0.0" lower="-3.14159" upper="3.14159" velocity="0.0"/>
    </joint>
    <joint name="RightUpperLeg0_RightLowerLeg0" type="revolute">
       <parent link="RightUpperLeg0"/>
       <child  link="RightLowerLeg0"/>
       <origin rpy="0 0 0" xyz="0 -0.09463019098167086 -0.2283564886587216" />
     <axis xyz="0 1 0"/>
       <limit effort="0.0" lower="-3.14159" upper="3.14159" velocity="0.0"/>
    </joint>
    <joint name="LeftUpperLeg0_LeftLowerLeg0" type="revolute">
       <parent link="LeftUpperLeg0"/>
       <child  link="LeftLowerLeg0"/>
       <origin rpy="0 0 0" xyz="0.21531451218780998 0 0" />
     <axis xyz="0 1 0"/>
       <limit effort="0.0" lower="-3.14159" upper="3.14159" velocity="0.0"/>
    </joint>
    <joint name="body1_RightUpperLeg1" type="revolute">
       <parent link="body1"/>
       <child  link="RightUpperLeg1"/>
       <origin rpy="0 0 0" xyz="0.2644864044056892 -0.26181293469603134 0" />
     <axis xyz="0 1 0"/>
       <limit effort="0.0" lower="-3.14159" upper="3.14159" velocity="0.0"/>
    </joint>
    <joint name="body1_LeftUpperLeg1" type="revolute">
       <parent link="body1"/>
       <child  link="LeftUpperLeg1"/>
       <origin rpy="0 0 0" xyz="0.2644864044056892 0.26181293469603134 0" />
     <axis xyz="0 1 0"/>
       <limit effort="0.0" lower="-3.14159" upper="3.14159" velocity="0.0"/>
    </joint>
    <joint name="RightUpperLeg1_RightLowerLeg1" type="revolute">
       <parent link="RightUpperLeg1"/>
       <child  link="RightLowerLeg1"/>
       <origin rpy="0 0 0" xyz="0 -0.09463019098167086 -0.2283564886587216" />
     <axis xyz="0 1 0"/>
       <limit effort="0.0" lower="-3.14159" upper="3.14159" velocity="0.0"/>
    </joint>
    <joint name="LeftUpperLeg1_LeftLowerLeg1" type="revolute">
       <parent link="LeftUpperLeg1"/>
       <child  link="LeftLowerLeg1"/>
       <origin rpy="0 0 0" xyz="0 0.09463019098167086 -0.2283564886587216" />
     <axis xyz="0 1 0"/>
       <limit effort="0.0" lower="-3.14159" upper="3.14159" velocity="0.0"/>
    </joint>
</robot>