<robot name = "robot">
    <link name="body0">
        <inertial>
            <origin xyz="0.22899262899209105 0 0.8441950543343525" rpy="0 0 0"/>
            <mass value="1" />
            <inertia ixx="100" ixy="0" ixz="0" iyy="100" iyz="0" izz="100" />
        </inertial>
        <visual>
            <origin xyz="0.22899262899209105 0 0.8441950543343525" rpy="0 0 0"/>
            <geometry>
                <box size="0.4579852579841821 0.5013787519686824 0.14640040432036897" />
            </geometry>
            <material name="green">
                <color rgba="0 1.0 0 1.0"/>
            </material>
        </visual>
        <collision>
            <origin xyz="0.22899262899209105 0 0.8441950543343525" rpy="0 0 0"/>
            <geometry>
                <box size="0.4579852579841821 0.5013787519686824 0.14640040432036897" />
            </geometry>
        </collision>
    </link>
    <link name="RightUpperLeg0">
        <inertial>
            <origin xyz="0 -0.17975303779684754 -0.3072867268417854" rpy="0 0 0"/>
            <mass value="1" />
            <inertia ixx="100" ixy="0" ixz="0" iyy="100" iyz="0" izz="100" />
        </inertial>
        <visual>
            <origin xyz="0 -0.17975303779684754 -0.3072867268417854" rpy="0 0 0"/>
            <geometry>
                <box size="0.25544576468256674 0.3595060755936951 0.6145734536835707" />
            </geometry>
            <material name="green">
                <color rgba="0 1.0 0 1.0"/>
            </material>
        </visual>
        <collision>
            <origin xyz="0 -0.17975303779684754 -0.3072867268417854" rpy="0 0 0"/>
            <geometry>
                <box size="0.25544576468256674 0.3595060755936951 0.6145734536835707" />
            </geometry>
        </collision>
    </link>
    <link name="LeftUpperLeg0">
        <inertial>
            <origin xyz="0 0.17975303779684754 -0.3072867268417854" rpy="0 0 0"/>
            <mass value="1" />
            <inertia ixx="100" ixy="0" ixz="0" iyy="100" iyz="0" izz="100" />
        </inertial>
        <visual>
            <origin xyz="0 0.17975303779684754 -0.3072867268417854" rpy="0 0 0"/>
            <geometry>
                <box size="0.25544576468256674 0.3595060755936951 0.6145734536835707" />
            </geometry>
            <material name="red">
                <color rgba="0 0 1.0 1.0"/>
            </material>
        </visual>
        <collision>
            <origin xyz="0 0.17975303779684754 -0.3072867268417854" rpy="0 0 0"/>
            <geometry>
                <box size="0.25544576468256674 0.3595060755936951 0.6145734536835707" />
            </geometry>
        </collision>
    </link>
    <link name="RightLowerLeg0">
        <inertial>
            <origin xyz="0 0 -0.11481080032539087" rpy="0 0 0"/>
            <mass value="1" />
            <inertia ixx="100" ixy="0" ixz="0" iyy="100" iyz="0" izz="100" />
        </inertial>
        <visual>
            <origin xyz="0 0 -0.11481080032539087" rpy="0 0 0"/>
            <geometry>
                <box size="0.34888100781825515 0.18191499226502422 0.22962160065078174" />
            </geometry>
            <material name="red">
                <color rgba="0 0 1.0 1.0"/>
            </material>
        </visual>
        <collision>
            <origin xyz="0 0 -0.11481080032539087" rpy="0 0 0"/>
            <geometry>
                <box size="0.34888100781825515 0.18191499226502422 0.22962160065078174" />
            </geometry>
        </collision>
    </link>
    <link name="LeftLowerLeg0">
        <inertial>
            <origin xyz="0 0 -0.11481080032539087" rpy="0 0 0"/>
            <mass value="1" />
            <inertia ixx="100" ixy="0" ixz="0" iyy="100" iyz="0" izz="100" />
        </inertial>
        <visual>
            <origin xyz="0 0 -0.11481080032539087" rpy="0 0 0"/>
            <geometry>
                <box size="0.34888100781825515 0.18191499226502422 0.22962160065078174" />
            </geometry>
            <material name="green">
                <color rgba="0 1.0 0 1.0"/>
            </material>
        </visual>
        <collision>
            <origin xyz="0 0 -0.11481080032539087" rpy="0 0 0"/>
            <geometry>
                <box size="0.34888100781825515 0.18191499226502422 0.22962160065078174" />
            </geometry>
        </collision>
    </link>
    <link name="body1">
        <inertial>
            <origin xyz="0.22899262899209105 0 0" rpy="0 0 0"/>
            <mass value="1" />
            <inertia ixx="100" ixy="0" ixz="0" iyy="100" iyz="0" izz="100" />
        </inertial>
        <visual>
            <origin xyz="0.22899262899209105 0 0" rpy="0 0 0"/>
            <geometry>
                <box size="0.4579852579841821 0.5013787519686824 0.14640040432036897" />
            </geometry>
            <material name="red">
                <color rgba="0 0 1.0 1.0"/>
            </material>
        </visual>
        <collision>
            <origin xyz="0.22899262899209105 0 0" rpy="0 0 0"/>
            <geometry>
                <box size="0.4579852579841821 0.5013787519686824 0.14640040432036897" />
            </geometry>
        </collision>
    </link>
    <link name="RightUpperLeg1">
        <inertial>
            <origin xyz="0 -0.17975303779684754 -0.3072867268417854" rpy="0 0 0"/>
            <mass value="1" />
            <inertia ixx="100" ixy="0" ixz="0" iyy="100" iyz="0" izz="100" />
        </inertial>
        <visual>
            <origin xyz="0 -0.17975303779684754 -0.3072867268417854" rpy="0 0 0"/>
            <geometry>
                <box size="0.25544576468256674 0.3595060755936951 0.6145734536835707" />
            </geometry>
            <material name="red">
                <color rgba="0 0 1.0 1.0"/>
            </material>
        </visual>
        <collision>
            <origin xyz="0 -0.17975303779684754 -0.3072867268417854" rpy="0 0 0"/>
            <geometry>
                <box size="0.25544576468256674 0.3595060755936951 0.6145734536835707" />
            </geometry>
        </collision>
    </link>
    <link name="LeftUpperLeg1">
        <inertial>
            <origin xyz="0 0.17975303779684754 -0.3072867268417854" rpy="0 0 0"/>
            <mass value="1" />
            <inertia ixx="100" ixy="0" ixz="0" iyy="100" iyz="0" izz="100" />
        </inertial>
        <visual>
            <origin xyz="0 0.17975303779684754 -0.3072867268417854" rpy="0 0 0"/>
            <geometry>
                <box size="0.25544576468256674 0.3595060755936951 0.6145734536835707" />
            </geometry>
            <material name="red">
                <color rgba="0 0 1.0 1.0"/>
            </material>
        </visual>
        <collision>
            <origin xyz="0 0.17975303779684754 -0.3072867268417854" rpy="0 0 0"/>
            <geometry>
                <box size="0.25544576468256674 0.3595060755936951 0.6145734536835707" />
            </geometry>
        </collision>
    </link>
    <link name="RightLowerLeg1">
        <inertial>
            <origin xyz="0 0 -0.11481080032539087" rpy="0 0 0"/>
            <mass value="1" />
            <inertia ixx="100" ixy="0" ixz="0" iyy="100" iyz="0" izz="100" />
        </inertial>
        <visual>
            <origin xyz="0 0 -0.11481080032539087" rpy="0 0 0"/>
            <geometry>
                <box size="0.34888100781825515 0.18191499226502422 0.22962160065078174" />
            </geometry>
            <material name="red">
                <color rgba="0 0 1.0 1.0"/>
            </material>
        </visual>
        <collision>
            <origin xyz="0 0 -0.11481080032539087" rpy="0 0 0"/>
            <geometry>
                <box size="0.34888100781825515 0.18191499226502422 0.22962160065078174" />
            </geometry>
        </collision>
    </link>
    <link name="LeftLowerLeg1">
        <inertial>
            <origin xyz="0 0 -0.11481080032539087" rpy="0 0 0"/>
            <mass value="1" />
            <inertia ixx="100" ixy="0" ixz="0" iyy="100" iyz="0" izz="100" />
        </inertial>
        <visual>
            <origin xyz="0 0 -0.11481080032539087" rpy="0 0 0"/>
            <geometry>
                <box size="0.34888100781825515 0.18191499226502422 0.22962160065078174" />
            </geometry>
            <material name="green">
                <color rgba="0 1.0 0 1.0"/>
            </material>
        </visual>
        <collision>
            <origin xyz="0 0 -0.11481080032539087" rpy="0 0 0"/>
            <geometry>
                <box size="0.34888100781825515 0.18191499226502422 0.22962160065078174" />
            </geometry>
        </collision>
    </link>
    <link name="body2">
        <inertial>
            <origin xyz="0.22899262899209105 0 0" rpy="0 0 0"/>
            <mass value="1" />
            <inertia ixx="100" ixy="0" ixz="0" iyy="100" iyz="0" izz="100" />
        </inertial>
        <visual>
            <origin xyz="0.22899262899209105 0 0" rpy="0 0 0"/>
            <geometry>
                <box size="0.4579852579841821 0.5013787519686824 0.14640040432036897" />
            </geometry>
            <material name="green">
                <color rgba="0 1.0 0 1.0"/>
            </material>
        </visual>
        <collision>
            <origin xyz="0.22899262899209105 0 0" rpy="0 0 0"/>
            <geometry>
                <box size="0.4579852579841821 0.5013787519686824 0.14640040432036897" />
            </geometry>
        </collision>
    </link>
    <link name="RightUpperLeg2">
        <inertial>
            <origin xyz="0 -0.17975303779684754 -0.3072867268417854" rpy="0 0 0"/>
            <mass value="1" />
            <inertia ixx="100" ixy="0" ixz="0" iyy="100" iyz="0" izz="100" />
        </inertial>
        <visual>
            <origin xyz="0 -0.17975303779684754 -0.3072867268417854" rpy="0 0 0"/>
            <geometry>
                <box size="0.25544576468256674 0.3595060755936951 0.6145734536835707" />
            </geometry>
            <material name="red">
                <color rgba="0 0 1.0 1.0"/>
            </material>
        </visual>
        <collision>
            <origin xyz="0 -0.17975303779684754 -0.3072867268417854" rpy="0 0 0"/>
            <geometry>
                <box size="0.25544576468256674 0.3595060755936951 0.6145734536835707" />
            </geometry>
        </collision>
    </link>
    <link name="LeftUpperLeg2">
        <inertial>
            <origin xyz="0 0.17975303779684754 -0.3072867268417854" rpy="0 0 0"/>
            <mass value="1" />
            <inertia ixx="100" ixy="0" ixz="0" iyy="100" iyz="0" izz="100" />
        </inertial>
        <visual>
            <origin xyz="0 0.17975303779684754 -0.3072867268417854" rpy="0 0 0"/>
            <geometry>
                <box size="0.25544576468256674 0.3595060755936951 0.6145734536835707" />
            </geometry>
            <material name="red">
                <color rgba="0 0 1.0 1.0"/>
            </material>
        </visual>
        <collision>
            <origin xyz="0 0.17975303779684754 -0.3072867268417854" rpy="0 0 0"/>
            <geometry>
                <box size="0.25544576468256674 0.3595060755936951 0.6145734536835707" />
            </geometry>
        </collision>
    </link>
    <link name="RightLowerLeg2">
        <inertial>
            <origin xyz="0 0 -0.11481080032539087" rpy="0 0 0"/>
            <mass value="1" />
            <inertia ixx="100" ixy="0" ixz="0" iyy="100" iyz="0" izz="100" />
        </inertial>
        <visual>
            <origin xyz="0 0 -0.11481080032539087" rpy="0 0 0"/>
            <geometry>
                <box size="0.34888100781825515 0.18191499226502422 0.22962160065078174" />
            </geometry>
            <material name="green">
                <color rgba="0 1.0 0 1.0"/>
            </material>
        </visual>
        <collision>
            <origin xyz="0 0 -0.11481080032539087" rpy="0 0 0"/>
            <geometry>
                <box size="0.34888100781825515 0.18191499226502422 0.22962160065078174" />
            </geometry>
        </collision>
    </link>
    <link name="LeftLowerLeg2">
        <inertial>
            <origin xyz="0 0 -0.11481080032539087" rpy="0 0 0"/>
            <mass value="1" />
            <inertia ixx="100" ixy="0" ixz="0" iyy="100" iyz="0" izz="100" />
        </inertial>
        <visual>
            <origin xyz="0 0 -0.11481080032539087" rpy="0 0 0"/>
            <geometry>
                <box size="0.34888100781825515 0.18191499226502422 0.22962160065078174" />
            </geometry>
            <material name="green">
                <color rgba="0 1.0 0 1.0"/>
            </material>
        </visual>
        <collision>
            <origin xyz="0 0 -0.11481080032539087" rpy="0 0 0"/>
            <geometry>
                <box size="0.34888100781825515 0.18191499226502422 0.22962160065078174" />
            </geometry>
        </collision>
    </link>
    <joint name="body0_body1" type="revolute">
       <parent link="body0"/>
       <child  link="body1"/>
       <origin rpy="0 0 0" xyz="0.4579852579841821 0 0.8441950543343525" />
     <axis xyz="0 1 0"/>
       <limit effort="0.0" lower="-3.14159" upper="3.14159" velocity="0.0"/>
    </joint>
    <joint name="body0_RightUpperLeg0" type="revolute">
       <parent link="body0"/>
       <child  link="RightUpperLeg0"/>
       <origin rpy="0 0 0" xyz="0.22899262899209105 -0.2506893759843412 0.8441950543343525" />
     <axis xyz="0 1 0"/>
       <limit effort="0.0" lower="-3.14159" upper="3.14159" velocity="0.0"/>
    </joint>
    <joint name="body0_LeftUpperLeg0" type="revolute">
       <parent link="body0"/>
       <child  link="LeftUpperLeg0"/>
       <origin rpy="0 0 0" xyz="0.22899262899209105 0.2506893759843412 0.8441950543343525" />
     <axis xyz="0 1 0"/>
       <limit effort="0.0" lower="-3.14159" upper="3.14159" velocity="0.0"/>
    </joint>
    <joint name="RightUpperLeg0_RightLowerLeg0" type="revolute">
       <parent link="RightUpperLeg0"/>
       <child  link="RightLowerLeg0"/>
       <origin rpy="0 0 0" xyz="0 -0.17975303779684754 -0.6145734536835707" />
     <axis xyz="0 1 0"/>
       <limit effort="0.0" lower="-3.14159" upper="3.14159" velocity="0.0"/>
    </joint>
    <joint name="LeftUpperLeg0_LeftLowerLeg0" type="revolute">
       <parent link="LeftUpperLeg0"/>
       <child  link="LeftLowerLeg0"/>
       <origin rpy="0 0 0" xyz="0 0.17975303779684754 -0.6145734536835707" />
     <axis xyz="0 1 0"/>
       <limit effort="0.0" lower="-3.14159" upper="3.14159" velocity="0.0"/>
    </joint>
    <joint name="body1_body2" type="revolute">
       <parent link="body1"/>
       <child  link="body2"/>
       <origin rpy="0 0 0" xyz="0.4579852579841821 0 0" />
     <axis xyz="0 1 0"/>
       <limit effort="0.0" lower="-3.14159" upper="3.14159" velocity="0.0"/>
    </joint>
    <joint name="body1_RightUpperLeg1" type="revolute">
       <parent link="body1"/>
       <child  link="RightUpperLeg1"/>
       <origin rpy="0 0 0" xyz="0.22899262899209105 -0.2506893759843412 0" />
     <axis xyz="0 1 0"/>
       <limit effort="0.0" lower="-3.14159" upper="3.14159" velocity="0.0"/>
    </joint>
    <joint name="body1_LeftUpperLeg1" type="revolute">
       <parent link="body1"/>
       <child  link="LeftUpperLeg1"/>
       <origin rpy="0 0 0" xyz="0.22899262899209105 0.2506893759843412 0" />
     <axis xyz="0 1 0"/>
       <limit effort="0.0" lower="-3.14159" upper="3.14159" velocity="0.0"/>
    </joint>
    <joint name="RightUpperLeg1_RightLowerLeg1" type="revolute">
       <parent link="RightUpperLeg1"/>
       <child  link="RightLowerLeg1"/>
       <origin rpy="0 0 0" xyz="0 -0.17975303779684754 -0.6145734536835707" />
     <axis xyz="0 1 0"/>
       <limit effort="0.0" lower="-3.14159" upper="3.14159" velocity="0.0"/>
    </joint>
    <joint name="LeftUpperLeg1_LeftLowerLeg1" type="revolute">
       <parent link="LeftUpperLeg1"/>
       <child  link="LeftLowerLeg1"/>
       <origin rpy="0 0 0" xyz="0.25544576468256674 0 0" />
     <axis xyz="0 1 0"/>
       <limit effort="0.0" lower="-3.14159" upper="3.14159" velocity="0.0"/>
    </joint>
    <joint name="body2_RightUpperLeg2" type="revolute">
       <parent link="body2"/>
       <child  link="RightUpperLeg2"/>
       <origin rpy="0 0 0" xyz="0.22899262899209105 -0.2506893759843412 0" />
     <axis xyz="0 1 0"/>
       <limit effort="0.0" lower="-3.14159" upper="3.14159" velocity="0.0"/>
    </joint>
    <joint name="body2_LeftUpperLeg2" type="revolute">
       <parent link="body2"/>
       <child  link="LeftUpperLeg2"/>
       <origin rpy="0 0 0" xyz="0.22899262899209105 0.2506893759843412 0" />
     <axis xyz="0 1 0"/>
       <limit effort="0.0" lower="-3.14159" upper="3.14159" velocity="0.0"/>
    </joint>
    <joint name="RightUpperLeg2_RightLowerLeg2" type="revolute">
       <parent link="RightUpperLeg2"/>
       <child  link="RightLowerLeg2"/>
       <origin rpy="0 0 0" xyz="0 -0.17975303779684754 -0.6145734536835707" />
     <axis xyz="0 1 0"/>
       <limit effort="0.0" lower="-3.14159" upper="3.14159" velocity="0.0"/>
    </joint>
    <joint name="LeftUpperLeg2_LeftLowerLeg2" type="revolute">
       <parent link="LeftUpperLeg2"/>
       <child  link="LeftLowerLeg2"/>
       <origin rpy="0 0 0" xyz="0 0.17975303779684754 -0.6145734536835707" />
     <axis xyz="0 1 0"/>
       <limit effort="0.0" lower="-3.14159" upper="3.14159" velocity="0.0"/>
    </joint>
</robot>